Workbook
Name BMS: 'Výpočty '!$F$5
Name CAPEX: 'Výpočty '!$D$1
Name Datalogger: 'Výpočty '!$F$3
Name Degradace: 'Výpočty '!$D$6
Name Diskontní_sazba: 'Výpočty '!$D$4
Name DOD: 'Výpočty '!$B$2
Name Hybridní_střídač: 'Výpočty '!$F$4
Name Kapacita_baterie: 'Výpočty '!$B$1
Name LCOE: 'Výpočty '!$C$11
Name OPEX: 'Výpočty '!$D$2
Name Roční_výroba: 'Výpočty '!$D$5
Name Smart_meter: 'Výpočty '!$F$2
Name Soc_Kriticke: 'Výpočty '!$B$7
Name Soc_Max: 'Výpočty '!$B$3
Name Soc_Min: 'Výpočty '!$B$4
Name Stridac_limit: 'Výpočty '!$B$5
Name Účinnost_cyklu: 'Výpočty '!$B$6
Name Vlastní_Spotřeba_kWh: 'Výpočty '!$F$6
Name Životnost: 'Výpočty '!$D$3

Sheet Výpočty 
A1: Kapacita baterie | B1: 20 | C1: CAPEX | D1: 400000 | E1: Amortizace | F1: =200000/(Kapacita_baterie*6000) -> 1.6666667 | G1: Kč/kWh | H1: Hybridní střídač | I1: BMS | J1: Smart meter | K1: Datalogger | N1: Ceník
A2: DOD | B2: =B3-B4 -> 0.8 | C2: OPEX | D2: 3000 | E2: Smart meter | F2: 5 | G2: W | H2: kWh | I2: =BMS/4000 + IF(OR(H3/Kapacita_baterie > 0.95, H3/Kapacita_baterie < 0.15), BMS/4000, 0) -> 0.0075 | J2: =Smart_meter/4000 -> 0.00125 | K2: =Datalogger/4000 -> 0.00075 | N2: Položka ceníku | O2: Jednotka
A3: Soc Max | B3: 0.9 | C3: Životnost | D3: 15 | E3: Datalogger | F3: 3 | G3: W | H3: =Hybridní_střídač/4000 -> 0.0125 | I3: =BMS/4000 + IF(OR(H3/Kapacita_baterie > 0.95, H3/Kapacita_baterie < 0.15), BMS/4000, 0) -> 0.0075 | J3: =Smart_meter/4000 -> 0.00125 | K3: =Datalogger/4000 -> 0.00075 | N3: 1. OBCHODNÍ CENA ZA DODÁVKU ELEKTŘINY (SILOVÁ ELEKTŘINA)
A4: Soc Min | B4: 0.1 | C4: Diskontní sazba | D4: 0.05 | E4: Hybridní střídač | F4: 50 | G4: W | H4: =Hybridní_střídač/4000 -> 0.0125 | I4: =BMS/4000 + IF(OR(H5/Kapacita_baterie > 0.95, H5/Kapacita_baterie < 0.15), BMS/4000, 0) -> 0.0075 | J4: =Smart_meter/4000 -> 0.00125 | K4: =Datalogger/4000 -> 0.00075 | N4: Distribuční sazba | P4: Klasika | R4: Aku | U4: Kombi | W4: Přímotop | Z4: Víkend
A5: Stridac limit | B5: 3.75 | C5: Roční výroba | D5: 15000 | E5: BMS | F5: 15 | G5: W | H5: =Hybridní_střídač/4000 -> 0.0125 | I5: =BMS/4000 + IF(OR(H6/Kapacita_baterie > 0.95, H6/Kapacita_baterie < 0.15), BMS/4000, 0) -> 0.0075 | J5: =Smart_meter/4000 -> 0.00125 | K5: =Datalogger/4000 -> 0.00075 | P5: D01d | Q5: D02d | R5: D25d | S5: D26d | T5: D27d | U5: D35d | W5: D45d | X5: D56d | Y5: D57d | Z5: D61d
A6: Účinnost cyklu | B6: 0.9 | C6: Degradace | D6: 0.005 | E6: Vlastní Spotřeba | F6: =(Smart_meter+Datalogger+Hybridní_střídač+BMS)/4000 -> 0.01825 | G6: kWh | H6: =Hybridní_střídač/4000 -> 0.0125 | I6: =BMS/4000 + IF(OR(H7/Kapacita_baterie > 0.95, H7/Kapacita_baterie < 0.15), BMS/4000, 0) -> 0.0075 | J6: =Smart_meter/4000 -> 0.00125 | K6: =Datalogger/4000 -> 0.00075 | N6: Cena ve vysokém tarigu (VT) | O6: Kč/MWh | P6: 4792.81 | R6: 5009.4 | U6: 5043.28 | W6: 5034.81 | Z6: 5026.34
A7: Soc Kriticke | B7: 0.05 | F7: =4*Vlastní_Spotřeba_kWh -> 0.073 | H7: =Hybridní_střídač/4000 -> 0.0125 | I7: =BMS/4000 + IF(OR(H8/Kapacita_baterie > 0.95, H8/Kapacita_baterie < 0.15), BMS/4000, 0) -> 0.0075 | J7: =Smart_meter/4000 -> 0.00125 | K7: =Datalogger/4000 -> 0.00075 | P7: 3961 | R7: 4140 | U7: 4168 | W7: 4161 | Z7: 4154
H8: =Hybridní_střídač/4000 -> 0.0125 | I8: =BMS/4000 + IF(OR(H9/Kapacita_baterie > 0.95, H9/Kapacita_baterie < 0.15), BMS/4000, 0) -> 0.0075 | J8: =Smart_meter/4000 -> 0.00125 | K8: =Datalogger/4000 -> 0.00075 | N8: Cena v nźkém tarifu (NT) | O8: Kč/MWh | R8: 4508.46 | U8: 4675.44 | W8: 4769.82 | Z8: 4507.25
A9: Soběstačnost | H9: =Hybridní_střídač/4000 -> 0.0125 | I9: =BMS/4000 + IF(OR(H10/Kapacita_baterie > 0.95, H10/Kapacita_baterie < 0.15), BMS/4000, 0) -> 0.0075 | J9: =Smart_meter/4000 -> 0.00125 | K9: =Datalogger/4000 -> 0.00075 | R9: 3726 | U9: 3864 | W9: 3942 | Z9: 3725
A10: Roční výroba | C10: 14000 | H10: =Hybridní_střídač/4000 -> 0.0125 | I10: =BMS/4000 + IF(OR(H11/Kapacita_baterie > 0.95, H11/Kapacita_baterie < 0.15), BMS/4000, 0) -> 0.0075 | J10: =Smart_meter/4000 -> 0.00125 | K10: =Datalogger/4000 -> 0.00075 | N10: Stalý měsíční plat | O10: Kč/MWh | P10: 145.2
A11: LCOE | C11: =(CAPEX + PV(Diskontní_sazba, Životnost, -OPEX)) / PV(Diskontní_sazba, Životnost, -Roční_výroba) -> 2.7691277 | D11: Kč/kWh | H11: =Hybridní_střídač/4000 -> 0.0125 | I11: =BMS/4000 + IF(OR(H12/Kapacita_baterie > 0.95, H12/Kapacita_baterie < 0.15), BMS/4000, 0) -> 0.0075 | J11: =Smart_meter/4000 -> 0.00125 | K11: =Datalogger/4000 -> 0.00075 | P11: 120
A12: Cena kWh z baterie | C12: =(LCOE / Účinnost_cyklu) -> 3.0768085 | D12: Kč/kWh | H12: =Hybridní_střídač/4000 -> 0.0125 | I12: =BMS/4000 + IF(OR(H13/Kapacita_baterie > 0.95, H13/Kapacita_baterie < 0.15), BMS/4000, 0) -> 0.0075 | J12: =Smart_meter/4000 -> 0.00125 | K12: =Datalogger/4000 -> 0.00075
C13: (LCOE/Úč. Cyklu) | H13: =Hybridní_střídač/4000 -> 0.0125 | I13: =BMS/4000 + IF(OR(H14/Kapacita_baterie > 0.95, H14/Kapacita_baterie < 0.15), BMS/4000, 0) -> 0.0075 | J13: =Smart_meter/4000 -> 0.00125 | K13: =Datalogger/4000 -> 0.00075 | N13: 2. REGULOVANÁ CENA ZA DISTRIBUCI (ÚZEMÍ EG.D)
H14: =Hybridní_střídač/4000 -> 0.0125 | I14: =BMS/4000 + IF(OR(H15/Kapacita_baterie > 0.95, H15/Kapacita_baterie < 0.15), BMS/4000, 0) -> 0.0075 | J14: =Smart_meter/4000 -> 0.00125 | K14: =Datalogger/4000 -> 0.00075 | N14: Cena za distribuci
H15: =Hybridní_střídač/4000 -> 0.0125 | I15: =BMS/4000 + IF(OR(H16/Kapacita_baterie > 0.95, H16/Kapacita_baterie < 0.15), BMS/4000, 0) -> 0.0075 | J15: =Smart_meter/4000 -> 0.00125 | K15: =Datalogger/4000 -> 0.00075 | N15: Cena ve vysokém tarigu (VT) | O15: Kč/MWh | P15: 3148.06 | Q15: 2438.95 | R15: 2607.76 | S15: 1376.99 | T15: 2607.76 | U15: 784.83 | V15: 784.83 | W15: 784.83 | X15: 784.83 | Y15: 3631.27
H16: =Hybridní_střídač/4000 -> 0.0125 | I16: =BMS/4000 + IF(OR(H17/Kapacita_baterie > 0.95, H17/Kapacita_baterie < 0.15), BMS/4000, 0) -> 0.0075 | J16: =Smart_meter/4000 -> 0.00125 | K16: =Datalogger/4000 -> 0.00075 | P16: 2601.7 | Q16: 2015.66 | R16: 2155.17 | S16: 1138.01 | T16: 2155.17 | U16: 648.82 | V16: 648.82 | W16: 648.82 | X16: 648.82 | Y16: 3001.05
H17: =Hybridní_střídač/4000 -> 0.0125 | I17: =BMS/4000 + IF(OR(H18/Kapacita_baterie > 0.95, H18/Kapacita_baterie < 0.15), BMS/4000, 0) -> 0.0075 | J17: =Smart_meter/4000 -> 0.00125 | K17: =Datalogger/4000 -> 0.00075 | N17: Cena v nźkém tarifu (NT) | O17: Kč/MWh | P17: 0 | Q17: 0 | R17: 530.09 | S17: 530.09 | T17: 530.09 | U17: 530.09 | V17: 530.09 | W17: 530.09 | X17: 530.09 | Y17: 530.09
H18: =Hybridní_střídač/4000 -> 0.0125 | I18: =BMS/4000 + IF(OR(H19/Kapacita_baterie > 0.95, H19/Kapacita_baterie < 0.15), BMS/4000, 0) -> 0.0075 | J18: =Smart_meter/4000 -> 0.00125 | K18: =Datalogger/4000 -> 0.00075 | P18: 0 | Q18: 0 | R18: 438.09 | S18: 438.09 | T18: 438.09 | U18: 438.09 | V18: 438.09 | W18: 438.09 | X18: 438.09 | Y18: 438.09
H19: =Hybridní_střídač/4000 -> 0.0125 | I19: =BMS/4000 + IF(OR(H20/Kapacita_baterie > 0.95, H20/Kapacita_baterie < 0.15), BMS/4000, 0) -> 0.0075 | J19: =Smart_meter/4000 -> 0.00125 | K19: =Datalogger/4000 -> 0.00075
H20: =Hybridní_střídač/4000 -> 0.0125 | I20: =BMS/4000 + IF(OR(H21/Kapacita_baterie > 0.95, H21/Kapacita_baterie < 0.15), BMS/4000, 0) -> 0.0075 | J20: =Smart_meter/4000 -> 0.00125 | K20: =Datalogger/4000 -> 0.00075 | N20: Měsíční plat za příkon dle hodnoty hlavního jističe:
H21: =Hybridní_střídač/4000 -> 0.0125 | I21: =BMS/4000 + IF(OR(H22/Kapacita_baterie > 0.95, H22/Kapacita_baterie < 0.15), BMS/4000, 0) -> 0.0075 | J21: =Smart_meter/4000 -> 0.00125 | K21: =Datalogger/4000 -> 0.00075 | N21: do 3x10 A a do 1x25 A včetně | O21: Kč/měsíc | P21: 44 | Q21: 99 | R21: 96 | S21: 140 | T21: 91 | U21: 166 | V21: 189 | W21: 189 | X21: 189 | Y21: 80
H22: =Hybridní_střídač/4000 -> 0.0125 | I22: =BMS/4000 + IF(OR(H23/Kapacita_baterie > 0.95, H23/Kapacita_baterie < 0.15), BMS/4000, 0) -> 0.0075 | J22: =Smart_meter/4000 -> 0.00125 | K22: =Datalogger/4000 -> 0.00075 | P22: 36 | Q22: 82 | R22: 79 | S22: 116 | T22: 75 | U22: 137 | V22: 156 | W22: 156 | X22: 156 | Y22: 66
H23: =Hybridní_střídač/4000 -> 0.0125 | I23: =BMS/4000 + IF(OR(H24/Kapacita_baterie > 0.95, H24/Kapacita_baterie < 0.15), BMS/4000, 0) -> 0.0075 | J23: =Smart_meter/4000 -> 0.00125 | K23: =Datalogger/4000 -> 0.00075 | N23: nad 3x10 A do 3x16 A včetně | O23: Kč/měsíc | P23: 70 | Q23: 159 | R23: 152 | S23: 225 | T23: 145 | U23: 265 | V23: 303 | W23: 303 | X23: 303 | Y23: 127
H24: =Hybridní_střídač/4000 -> 0.0125 | I24: =BMS/4000 + IF(OR(H25/Kapacita_baterie > 0.95, H25/Kapacita_baterie < 0.15), BMS/4000, 0) -> 0.0075 | J24: =Smart_meter/4000 -> 0.00125 | K24: =Datalogger/4000 -> 0.00075 | P24: 58 | Q24: 131 | R24: 126 | S24: 186 | T24: 120 | U24: 219 | V24: 250 | W24: 250 | X24: 250 | Y24: 105
H25: =Hybridní_střídač/4000 -> 0.0125 | I25: =BMS/4000 + IF(OR(H26/Kapacita_baterie > 0.95, H26/Kapacita_baterie < 0.15), BMS/4000, 0) -> 0.0075 | J25: =Smart_meter/4000 -> 0.00125 | K25: =Datalogger/4000 -> 0.00075 | N25: nad 3x16 A do 3x20 A včetně | O25: Kč/měsíc | P25: 88 | Q25: 198 | R25: 191 | S25: 281 | T25: 182 | U25: 332 | V25: , 379 | W25: 379 | X25: 378 | Y25: 159
H26: =Hybridní_střídač/4000 -> 0.0125 | I26: =BMS/4000 + IF(OR(H27/Kapacita_baterie > 0.95, H27/Kapacita_baterie < 0.15), BMS/4000, 0) -> 0.0075 | J26: =Smart_meter/4000 -> 0.00125 | K26: =Datalogger/4000 -> 0.00075 | P26: 73 | Q26: 164 | R26: 158 | S26: 232 | T26: 150 | U26: 274 | V26: 313 | W26: 313 | X26: 312 | Y26: 131
H27: =Hybridní_střídač/4000 -> 0.0125 | I27: =BMS/4000 + IF(OR(H28/Kapacita_baterie > 0.95, H28/Kapacita_baterie < 0.15), BMS/4000, 0) -> 0.0075 | J27: =Smart_meter/4000 -> 0.00125 | K27: =Datalogger/4000 -> 0.00075 | N27: nad 3x20 A do 3x25 A včetně | O27: Kč/měsíc | P27: 110 | Q27: 248 | R27: 238 | S27: 351 | T27: 227 | U27: 414 | V27: 473 | W27: 473 | X27: 473 | Y27: 198
H28: =Hybridní_střídač/4000 -> 0.0125 | I28: =BMS/4000 + IF(OR(H29/Kapacita_baterie > 0.95, H29/Kapacita_baterie < 0.15), BMS/4000, 0) -> 0.0075 | J28: =Smart_meter/4000 -> 0.00125 | K28: =Datalogger/4000 -> 0.00075 | P28: 91 | Q28: 205 | R28: 197 | S28: 290 | T28: 188 | U28: 342 | V28: 391 | W28: 391 | X28: 391 | Y28: 164
H29: =Hybridní_střídač/4000 -> 0.0125 | I29: =BMS/4000 + IF(OR(H30/Kapacita_baterie > 0.95, H30/Kapacita_baterie < 0.15), BMS/4000, 0) -> 0.0075 | J29: =Smart_meter/4000 -> 0.00125 | K29: =Datalogger/4000 -> 0.00075 | N29: nad 3x25 A do 3x32 A včetně | O29: Kč/měsíc | P29: 140 | Q29: 317 | R29: 305 | S29: 450 | T29: 290 | U29: 530 | V29: 605 | W29: 605 | X29: 605 | Y29: 254
H30: =Hybridní_střídač/4000 -> 0.0125 | I30: =BMS/4000 + IF(OR(H31/Kapacita_baterie > 0.95, H31/Kapacita_baterie < 0.15), BMS/4000, 0) -> 0.0075 | J30: =Smart_meter/4000 -> 0.00125 | K30: =Datalogger/4000 -> 0.00075 | P30: 116 | Q30: 262 | R30: 252 | S30: 372 | T30: 240 | U30: 438 | V30: 500 | W30: 500 | X30: 500 | Y30: 210
H31: =Hybridní_střídač/4000 -> 0.0125 | I31: =BMS/4000 + IF(OR(H32/Kapacita_baterie > 0.95, H32/Kapacita_baterie < 0.15), BMS/4000, 0) -> 0.0075 | J31: =Smart_meter/4000 -> 0.00125 | K31: =Datalogger/4000 -> 0.00075 | N31: nad 3x32 A do 3x40 A včetně | O31: Kč/měsíc | P31: 175 | Q31: 397 | R31: 382 | S31: 561 | T31: 363 | U31: 662 | V31: 756 | W31: 756 | X31: 778 | Y31: 318
H32: =Hybridní_střídač/4000 -> 0.0125 | I32: =BMS/4000 + IF(OR(H33/Kapacita_baterie > 0.95, H33/Kapacita_baterie < 0.15), BMS/4000, 0) -> 0.0075 | J32: =Smart_meter/4000 -> 0.00125 | K32: =Datalogger/4000 -> 0.00075 | P32: 145 | Q32: 328 | R32: 316 | S32: 464 | T32: 300 | U32: 547 | V32: 625 | W32: 625 | X32: 643 | Y32: 263
H33: =Hybridní_střídač/4000 -> 0.0125 | I33: =BMS/4000 + IF(OR(H34/Kapacita_baterie > 0.95, H34/Kapacita_baterie < 0.15), BMS/4000, 0) -> 0.0075 | J33: =Smart_meter/4000 -> 0.00125 | K33: =Datalogger/4000 -> 0.00075 | N33: nad 3x40 A do 3x50 A včetně | O33: Kč/měsíc | P33: 220 | Q33: 496 | R33: 478 | S33: 703 | T33: 454 | U33: 828 | V33: 946 | W33: 946 | X33: 1168 | Y33: 398
H34: =Hybridní_střídač/4000 -> 0.0125 | I34: =BMS/4000 + IF(OR(H35/Kapacita_baterie > 0.95, H35/Kapacita_baterie < 0.15), BMS/4000, 0) -> 0.0075 | J34: =Smart_meter/4000 -> 0.00125 | K34: =Datalogger/4000 -> 0.00075 | P34: 182 | Q34: 410 | R34: 395 | S34: 581 | T34: 375 | U34: 684 | V34: 782 | W34: 782 | X34: 965 | Y34: 329
H35: =Hybridní_střídač/4000 -> 0.0125 | I35: =BMS/4000 + IF(OR(H36/Kapacita_baterie > 0.95, H36/Kapacita_baterie < 0.15), BMS/4000, 0) -> 0.0075 | J35: =Smart_meter/4000 -> 0.00125 | K35: =Datalogger/4000 -> 0.00075 | N35: nad 3x50 A do 3x63 A včetně | O35: Kč/měsíc | P35: 277 | Q35: 624 | R35: 601 | S35: 885 | T35: 572 | U35: 1043 | V35: 1192 | W35: 1192 | X35: 1715 | Y35: 501
H36: =Hybridní_střídač/4000 -> 0.0125 | I36: =BMS/4000 + IF(OR(H37/Kapacita_baterie > 0.95, H37/Kapacita_baterie < 0.15), BMS/4000, 0) -> 0.0075 | J36: =Smart_meter/4000 -> 0.00125 | K36: =Datalogger/4000 -> 0.00075 | P36: 229 | Q36: 516 | R36: 497 | S36: 731 | T36: 473 | U36: 862 | V36: 985 | W36: 985 | X36: 1417 | Y36: 414
H37: =Hybridní_střídač/4000 -> 0.0125 | I37: =BMS/4000 + IF(OR(H38/Kapacita_baterie > 0.95, H38/Kapacita_baterie < 0.15), BMS/4000, 0) -> 0.0075 | J37: =Smart_meter/4000 -> 0.00125 | K37: =Datalogger/4000 -> 0.00075 | N37: nad 3x63 A do 3x80 A včetně | O37: Kč/měsíc | P37: 0 | Q37: 0 | R37: 0 | S37: 0 | T37: 0 | U37: 0 | V37: 0 | W37: 0 | X37: 2840 | Y37: 0
H38: =Hybridní_střídač/4000 -> 0.0125 | I38: =BMS/4000 + IF(OR(H39/Kapacita_baterie > 0.95, H39/Kapacita_baterie < 0.15), BMS/4000, 0) -> 0.0075 | J38: =Smart_meter/4000 -> 0.00125 | K38: =Datalogger/4000 -> 0.00075 | P38: 0 | Q38: 0 | R38: 0 | S38: 0 | T38: 0 | U38: 0 | V38: 0 | W38: 0 | X38: 2347 | Y38: 0
H39: =Hybridní_střídač/4000 -> 0.0125 | I39: =BMS/4000 + IF(OR(H40/Kapacita_baterie > 0.95, H40/Kapacita_baterie < 0.15), BMS/4000, 0) -> 0.0075 | J39: =Smart_meter/4000 -> 0.00125 | K39: =Datalogger/4000 -> 0.00075 | N39: nad 3x80 A do 3x100 A včetně | O39: Kč/měsíc | P39: 0 | Q39: 0 | R39: 0 | S39: 0 | T39: 0 | U39: 0 | V39: 0 | W39: 0 | X39: 5241 | Y39: 0
H40: =Hybridní_střídač/4000 -> 0.0125 | I40: =BMS/4000 + IF(OR(H41/Kapacita_baterie > 0.95, H41/Kapacita_baterie < 0.15), BMS/4000, 0) -> 0.0075 | J40: =Smart_meter/4000 -> 0.00125 | K40: =Datalogger/4000 -> 0.00075 | P40: 0 | Q40: 0 | R40: 0 | S40: 0 | T40: 0 | U40: 0 | V40: 0 | W40: 0 | X40: 4331 | Y40: 0
...

Sheet Leden
A1: Datum | B1: Čas | C1: Spotřeba | D1: Přímá vlastní spotřeba z FVE | E1: Výroba FVE | F1: Odběr z DS | G1: Přetok do DS | H1: Spotřeba z baterie | I1: Bilance | J1: Stav baterie | K1: Soc | L1: Nabíjení (Netto) | M1: Nabíjení (Brutto) | N1: Vybíjení (Netto) | O1: Vybíjení (Brutto) | P1: Vlastní spotřeba
C2: kWh | D2: kwh | E2: kWh | F2: kWh | G2: kWh | H2: kWh | I2: kWh | J2: 10 | K2: % | L2: kWh | M2: kWh | N2: kWh | O2: kWh | P2: kWh
A3: =DATE(2026,1,1) -> 46023 | B3: =TIME(0,0,0) -> 0 | C3: ='Leden data'!V2+P3 -> 0.5445 | D3: =MIN(C3, E3) -> 0 | E3: =ROUND(MAX(0, 8.5 * EXP(-((HOUR(B3)+MINUTE(B3)/60 - 12)^2) / 2) * 0.25), 3) -> 0 | F3: =MAX(0, C3 - D3 - H3 ) -> 0 | G3: =MAX(0, E3 - D3 - M3) -> 0 | H3: =MAX(0, MIN(C3 - D3, N3 )) -> 0.5445 | I3: =E3-C3 -> -0.5445 | J3: =MIN('Výpočty '!$B$1*0.9, MAX('Výpočty '!$B$1*0.05, J2 + M3 - MIN(O3, MAX(0, J2 - ('Výpočty '!$B$1*0.1))) - P3)) -> 9.3564722 | K3: =J3/'Výpočty '!$B$1 -> 0.46782361 | L3: =M3 * Účinnost_cyklu -> 0 | M3: =MIN(MAX(0, I3), MAX(0, Kapacita_baterie * Soc_Max - J2) / Účinnost_cyklu, Stridac_limit) -> 0 | N3: =MAX(0, MIN(J2 - (Kapacita_baterie * Soc_Kriticke), C3 - D3 + P3)) -> 0.56275 | O3: =N3 / Účinnost_cyklu -> 0.62527778 | P3: =Vlastní_Spotřeba_kWh -> 0.01825
A4: =DATE(2026,1,1) -> 46023 | B4: =B3+TIME(0,15,0) -> 0.010416667 | C4: ='Leden data'!V3+P4 -> 0.5445 | D4: =MIN(C4, E4) -> 0 | E4: =ROUND(MAX(0, 8.5 * EXP(-((HOUR(B4)+MINUTE(B4)/60 - 12)^2) / 2) * 0.25), 3) -> 0 | F4: =MAX(0, C4 - D4 - H4 ) -> 0 | G4: =MAX(0, E4 - D4 - M4) -> 0 | H4: =MAX(0, MIN(C4 - D4, N4 )) -> 0.5445 | I4: =E4-C4 -> -0.5445 | J4: =MIN('Výpočty '!$B$1*0.9, MAX('Výpočty '!$B$1*0.05, J3 + M4 - MIN(O4, MAX(0, J3 - ('Výpočty '!$B$1*0.1))) - P4)) -> 8.7129444 | K4: =J4/'Výpočty '!$B$1 -> 0.43564722 | L4: =M4 * Účinnost_cyklu -> 0 | M4: =MIN(MAX(0, I4), MAX(0, Kapacita_baterie * Soc_Max - J3) / Účinnost_cyklu, Stridac_limit) -> 0 | N4: =MAX(0, MIN(J3 - (Kapacita_baterie * Soc_Kriticke), C4 - D4 + P4)) -> 0.56275 | O4: =N4 / Účinnost_cyklu -> 0.62527778 | P4: =Vlastní_Spotřeba_kWh -> 0.01825
A5: =DATE(2026,1,1) -> 46023 | B5: =B4+TIME(0,15,0) -> 0.020833333 | C5: ='Leden data'!V4+P5 -> 0.5445 | D5: =MIN(C5, E5) -> 0 | E5: =ROUND(MAX(0, 8.5 * EXP(-((HOUR(B5)+MINUTE(B5)/60 - 12)^2) / 2) * 0.25), 3) -> 0 | F5: =MAX(0, C5 - D5 - H5 ) -> 0 | G5: =MAX(0, E5 - D5 - M5) -> 0 | H5: =MAX(0, MIN(C5 - D5, N5 )) -> 0.5445 | I5: =E5-C5 -> -0.5445 | J5: =MIN('Výpočty '!$B$1*0.9, MAX('Výpočty '!$B$1*0.05, J4 + M5 - MIN(O5, MAX(0, J4 - ('Výpočty '!$B$1*0.1))) - P5)) -> 8.0694167 | K5: =J5/'Výpočty '!$B$1 -> 0.40347083 | L5: =M5 * Účinnost_cyklu -> 0 | M5: =MIN(MAX(0, I5), MAX(0, Kapacita_baterie * Soc_Max - J4) / Účinnost_cyklu, Stridac_limit) -> 0 | N5: =MAX(0, MIN(J4 - (Kapacita_baterie * Soc_Kriticke), C5 - D5 + P5)) -> 0.56275 | O5: =N5 / Účinnost_cyklu -> 0.62527778 | P5: =Vlastní_Spotřeba_kWh -> 0.01825
A6: =DATE(2026,1,1) -> 46023 | B6: =B5+TIME(0,15,0) -> 0.03125 | C6: ='Leden data'!V5+P6 -> 0.5445 | D6: =MIN(C6, E6) -> 0 | E6: =ROUND(MAX(0, 8.5 * EXP(-((HOUR(B6)+MINUTE(B6)/60 - 12)^2) / 2) * 0.25), 3) -> 0 | F6: =MAX(0, C6 - D6 - H6 ) -> 0 | G6: =MAX(0, E6 - D6 - M6) -> 0 | H6: =MAX(0, MIN(C6 - D6, N6 )) -> 0.5445 | I6: =E6-C6 -> -0.5445 | J6: =MIN('Výpočty '!$B$1*0.9, MAX('Výpočty '!$B$1*0.05, J5 + M6 - MIN(O6, MAX(0, J5 - ('Výpočty '!$B$1*0.1))) - P6)) -> 7.4258889 | K6: =J6/'Výpočty '!$B$1 -> 0.37129444 | L6: =M6 * Účinnost_cyklu -> 0 | M6: =MIN(MAX(0, I6), MAX(0, Kapacita_baterie * Soc_Max - J5) / Účinnost_cyklu, Stridac_limit) -> 0 | N6: =MAX(0, MIN(J5 - (Kapacita_baterie * Soc_Kriticke), C6 - D6 + P6)) -> 0.56275 | O6: =N6 / Účinnost_cyklu -> 0.62527778 | P6: =Vlastní_Spotřeba_kWh -> 0.01825
A7: =DATE(2026,1,1) -> 46023 | B7: =B6+TIME(0,15,0) -> 0.041666667 | C7: ='Leden data'!V6+P7 -> 0.5445 | D7: =MIN(C7, E7) -> 0 | E7: =ROUND(MAX(0, 8.5 * EXP(-((HOUR(B7)+MINUTE(B7)/60 - 12)^2) / 2) * 0.25), 3) -> 0 | F7: =MAX(0, C7 - D7 - H7 ) -> 0 | G7: =MAX(0, E7 - D7 - M7) -> 0 | H7: =MAX(0, MIN(C7 - D7, N7 )) -> 0.5445 | I7: =E7-C7 -> -0.5445 | J7: =MIN('Výpočty '!$B$1*0.9, MAX('Výpočty '!$B$1*0.05, J6 + M7 - MIN(O7, MAX(0, J6 - ('Výpočty '!$B$1*0.1))) - P7)) -> 6.7823611 | K7: =J7/'Výpočty '!$B$1 -> 0.33911806 | L7: =M7 * Účinnost_cyklu -> 0 | M7: =MIN(MAX(0, I7), MAX(0, Kapacita_baterie * Soc_Max - J6) / Účinnost_cyklu, Stridac_limit) -> 0 | N7: =MAX(0, MIN(J6 - (Kapacita_baterie * Soc_Kriticke), C7 - D7 + P7)) -> 0.56275 | O7: =N7 / Účinnost_cyklu -> 0.62527778 | P7: =Vlastní_Spotřeba_kWh -> 0.01825
A8: =DATE(2026,1,1) -> 46023 | B8: =B7+TIME(0,15,0) -> 0.052083333 | C8: ='Leden data'!V7+P8 -> 0.5445 | D8: =MIN(C8, E8) -> 0 | E8: =ROUND(MAX(0, 8.5 * EXP(-((HOUR(B8)+MINUTE(B8)/60 - 12)^2) / 2) * 0.25), 3) -> 0 | F8: =MAX(0, C8 - D8 - H8 ) -> 0 | G8: =MAX(0, E8 - D8 - M8) -> 0 | H8: =MAX(0, MIN(C8 - D8, N8 )) -> 0.5445 | I8: =E8-C8 -> -0.5445 | J8: =MIN('Výpočty '!$B$1*0.9, MAX('Výpočty '!$B$1*0.05, J7 + M8 - MIN(O8, MAX(0, J7 - ('Výpočty '!$B$1*0.1))) - P8)) -> 6.1388333 | K8: =J8/'Výpočty '!$B$1 -> 0.30694167 | L8: =M8 * Účinnost_cyklu -> 0 | M8: =MIN(MAX(0, I8), MAX(0, Kapacita_baterie * Soc_Max - J7) / Účinnost_cyklu, Stridac_limit) -> 0 | N8: =MAX(0, MIN(J7 - (Kapacita_baterie * Soc_Kriticke), C8 - D8 + P8)) -> 0.56275 | O8: =N8 / Účinnost_cyklu -> 0.62527778 | P8: =Vlastní_Spotřeba_kWh -> 0.01825
A9: =DATE(2026,1,1) -> 46023 | B9: =B8+TIME(0,15,0) -> 0.0625 | C9: ='Leden data'!V8+P9 -> 0.5445 | D9: =MIN(C9, E9) -> 0 | E9: =ROUND(MAX(0, 8.5 * EXP(-((HOUR(B9)+MINUTE(B9)/60 - 12)^2) / 2) * 0.25), 3) -> 0 | F9: =MAX(0, C9 - D9 - H9 ) -> 0 | G9: =MAX(0, E9 - D9 - M9) -> 0 | H9: =MAX(0, MIN(C9 - D9, N9 )) -> 0.5445 | I9: =E9-C9 -> -0.5445 | J9: =MIN('Výpočty '!$B$1*0.9, MAX('Výpočty '!$B$1*0.05, J8 + M9 - MIN(O9, MAX(0, J8 - ('Výpočty '!$B$1*0.1))) - P9)) -> 5.4953056 | K9: =J9/'Výpočty '!$B$1 -> 0.27476528 | L9: =M9 * Účinnost_cyklu -> 0 | M9: =MIN(MAX(0, I9), MAX(0, Kapacita_baterie * Soc_Max - J8) / Účinnost_cyklu, Stridac_limit) -> 0 | N9: =MAX(0, MIN(J8 - (Kapacita_baterie * Soc_Kriticke), C9 - D9 + P9)) -> 0.56275 | O9: =N9 / Účinnost_cyklu -> 0.62527778 | P9: =Vlastní_Spotřeba_kWh -> 0.01825
A10: =DATE(2026,1,1) -> 46023 | B10: =B9+TIME(0,15,0) -> 0.072916667 | C10: ='Leden data'!V9+P10 -> 0.5445 | D10: =MIN(C10, E10) -> 0 | E10: =ROUND(MAX(0, 8.5 * EXP(-((HOUR(B10)+MINUTE(B10)/60 - 12)^2) / 2) * 0.25), 3) -> 0 | F10: =MAX(0, C10 - D10 - H10 ) -> 0 | G10: =MAX(0, E10 - D10 - M10) -> 0 | H10: =MAX(0, MIN(C10 - D10, N10 )) -> 0.5445 | I10: =E10-C10 -> -0.5445 | J10: =MIN('Výpočty '!$B$1*0.9, MAX('Výpočty '!$B$1*0.05, J9 + M10 - MIN(O10, MAX(0, J9 - ('Výpočty '!$B$1*0.1))) - P10)) -> 4.8517778 | K10: =J10/'Výpočty '!$B$1 -> 0.24258889 | L10: =M10 * Účinnost_cyklu -> 0 | M10: =MIN(MAX(0, I10), MAX(0, Kapacita_baterie * Soc_Max - J9) / Účinnost_cyklu, Stridac_limit) -> 0 | N10: =MAX(0, MIN(J9 - (Kapacita_baterie * Soc_Kriticke), C10 - D10 + P10)) -> 0.56275 | O10: =N10 / Účinnost_cyklu -> 0.62527778 | P10: =Vlastní_Spotřeba_kWh -> 0.01825
A11: =DATE(2026,1,1) -> 46023 | B11: =B10+TIME(0,15,0) -> 0.083333333 | C11: ='Leden data'!V10+P11 -> 0.5445 | D11: =MIN(C11, E11) -> 0 | E11: =ROUND(MAX(0, 8.5 * EXP(-((HOUR(B11)+MINUTE(B11)/60 - 12)^2) / 2) * 0.25), 3) -> 0 | F11: =MAX(0, C11 - D11 - H11 ) -> 0 | G11: =MAX(0, E11 - D11 - M11) -> 0 | H11: =MAX(0, MIN(C11 - D11, N11 )) -> 0.5445 | I11: =E11-C11 -> -0.5445 | J11: =MIN('Výpočty '!$B$1*0.9, MAX('Výpočty '!$B$1*0.05, J10 + M11 - MIN(O11, MAX(0, J10 - ('Výpočty '!$B$1*0.1))) - P11)) -> 4.20825 | K11: =J11/'Výpočty '!$B$1 -> 0.2104125 | L11: =M11 * Účinnost_cyklu -> 0 | M11: =MIN(MAX(0, I11), MAX(0, Kapacita_baterie * Soc_Max - J10) / Účinnost_cyklu, Stridac_limit) -> 0 | N11: =MAX(0, MIN(J10 - (Kapacita_baterie * Soc_Kriticke), C11 - D11 + P11)) -> 0.56275 | O11: =N11 / Účinnost_cyklu -> 0.62527778 | P11: =Vlastní_Spotřeba_kWh -> 0.01825
A12: =DATE(2026,1,1) -> 46023 | B12: =B11+TIME(0,15,0) -> 0.09375 | C12: ='Leden data'!V11+P12 -> 0.52575 | D12: =MIN(C12, E12) -> 0 | E12: =ROUND(MAX(0, 8.5 * EXP(-((HOUR(B12)+MINUTE(B12)/60 - 12)^2) / 2) * 0.25), 3) -> 0 | F12: =MAX(0, C12 - D12 - H12 ) -> 0 | G12: =MAX(0, E12 - D12 - M12) -> 0 | H12: =MAX(0, MIN(C12 - D12, N12 )) -> 0.52575 | I12: =E12-C12 -> -0.52575 | J12: =MIN('Výpočty '!$B$1*0.9, MAX('Výpočty '!$B$1*0.05, J11 + M12 - MIN(O12, MAX(0, J11 - ('Výpočty '!$B$1*0.1))) - P12)) -> 3.5855556 | K12: =J12/'Výpočty '!$B$1 -> 0.17927778 | L12: =M12 * Účinnost_cyklu -> 0 | M12: =MIN(MAX(0, I12), MAX(0, Kapacita_baterie * Soc_Max - J11) / Účinnost_cyklu, Stridac_limit) -> 0 | N12: =MAX(0, MIN(J11 - (Kapacita_baterie * Soc_Kriticke), C12 - D12 + P12)) -> 0.544 | O12: =N12 / Účinnost_cyklu -> 0.60444444 | P12: =Vlastní_Spotřeba_kWh -> 0.01825
A13: =DATE(2026,1,1) -> 46023 | B13: =B12+TIME(0,15,0) -> 0.10416667 | C13: ='Leden data'!V12+P13 -> 0.52575 | D13: =MIN(C13, E13) -> 0 | E13: =ROUND(MAX(0, 8.5 * EXP(-((HOUR(B13)+MINUTE(B13)/60 - 12)^2) / 2) * 0.25), 3) -> 0 | F13: =MAX(0, C13 - D13 - H13 ) -> 0 | G13: =MAX(0, E13 - D13 - M13) -> 0 | H13: =MAX(0, MIN(C13 - D13, N13 )) -> 0.52575 | I13: =E13-C13 -> -0.52575 | J13: =MIN('Výpočty '!$B$1*0.9, MAX('Výpočty '!$B$1*0.05, J12 + M13 - MIN(O13, MAX(0, J12 - ('Výpočty '!$B$1*0.1))) - P13)) -> 2.9628611 | K13: =J13/'Výpočty '!$B$1 -> 0.14814306 | L13: =M13 * Účinnost_cyklu -> 0 | M13: =MIN(MAX(0, I13), MAX(0, Kapacita_baterie * Soc_Max - J12) / Účinnost_cyklu, Stridac_limit) -> 0 | N13: =MAX(0, MIN(J12 - (Kapacita_baterie * Soc_Kriticke), C13 - D13 + P13)) -> 0.544 | O13: =N13 / Účinnost_cyklu -> 0.60444444 | P13: =Vlastní_Spotřeba_kWh -> 0.01825
A14: =DATE(2026,1,1) -> 46023 | B14: =B13+TIME(0,15,0) -> 0.11458333 | C14: ='Leden data'!V13+P14 -> 0.52575 | D14: =MIN(C14, E14) -> 0 | E14: =ROUND(MAX(0, 8.5 * EXP(-((HOUR(B14)+MINUTE(B14)/60 - 12)^2) / 2) * 0.25), 3) -> 0 | F14: =MAX(0, C14 - D14 - H14 ) -> 0 | G14: =MAX(0, E14 - D14 - M14) -> 0 | H14: =MAX(0, MIN(C14 - D14, N14 )) -> 0.52575 | I14: =E14-C14 -> -0.52575 | J14: =MIN('Výpočty '!$B$1*0.9, MAX('Výpočty '!$B$1*0.05, J13 + M14 - MIN(O14, MAX(0, J13 - ('Výpočty '!$B$1*0.1))) - P14)) -> 2.3401667 | K14: =J14/'Výpočty '!$B$1 -> 0.11700833 | L14: =M14 * Účinnost_cyklu -> 0 | M14: =MIN(MAX(0, I14), MAX(0, Kapacita_baterie * Soc_Max - J13) / Účinnost_cyklu, Stridac_limit) -> 0 | N14: =MAX(0, MIN(J13 - (Kapacita_baterie * Soc_Kriticke), C14 - D14 + P14)) -> 0.544 | O14: =N14 / Účinnost_cyklu -> 0.60444444 | P14: =Vlastní_Spotřeba_kWh -> 0.01825
A15: =DATE(2026,1,1) -> 46023 | B15: =B14+TIME(0,15,0) -> 0.125 | C15: ='Leden data'!V14+P15 -> 0.52575 | D15: =MIN(C15, E15) -> 0 | E15: =ROUND(MAX(0, 8.5 * EXP(-((HOUR(B15)+MINUTE(B15)/60 - 12)^2) / 2) * 0.25), 3) -> 0 | F15: =MAX(0, C15 - D15 - H15 ) -> 0 | G15: =MAX(0, E15 - D15 - M15) -> 0 | H15: =MAX(0, MIN(C15 - D15, N15 )) -> 0.52575 | I15: =E15-C15 -> -0.52575 | J15: =MIN('Výpočty '!$B$1*0.9, MAX('Výpočty '!$B$1*0.05, J14 + M15 - MIN(O15, MAX(0, J14 - ('Výpočty '!$B$1*0.1))) - P15)) -> 1.98175 | K15: =J15/'Výpočty '!$B$1 -> 0.0990875 | L15: =M15 * Účinnost_cyklu -> 0 | M15: =MIN(MAX(0, I15), MAX(0, Kapacita_baterie * Soc_Max - J14) / Účinnost_cyklu, Stridac_limit) -> 0 | N15: =MAX(0, MIN(J14 - (Kapacita_baterie * Soc_Kriticke), C15 - D15 + P15)) -> 0.544 | O15: =N15 / Účinnost_cyklu -> 0.60444444 | P15: =Vlastní_Spotřeba_kWh -> 0.01825
... A98: =DATE(2026,1,1) -> 46023 | B98: =B97+TIME(0,15,0) -> 0.98958333 | C98: ='Leden data'!V97+P98 -> 0.54075 | D98: =MIN(C98, E98) -> 0 | E98: =ROUND(MAX(0, 8.5 * EXP(-((HOUR(B98)+MINUTE(B98)/60 - 12)^2) / 2) * 0.25), 3) -> 0 | F98: =MAX(0, C98 - D98 - H98 ) -> 0 | G98: =MAX(0, E98 - D98 - M98) -> 0 | H98: =MAX(0, MIN(C98 - D98, N98 )) -> 0.54075 | I98: =E98-C98 -> -0.54075 | J98: =MIN('Výpočty '!$B$1*0.9, MAX('Výpočty '!$B$1*0.05, J97 + M98 - MIN(O98, MAX(0, J97 - ('Výpočty '!$B$1*0.1))) - P98)) -> 1.562 | K98: =J98/'Výpočty '!$B$1 -> 0.0781 | L98: =M98 * Účinnost_cyklu -> 0 | M98: =MIN(MAX(0, I98), MAX(0, Kapacita_baterie * Soc_Max - J97) / Účinnost_cyklu, Stridac_limit) -> 0 | N98: =MAX(0, MIN(J97 - (Kapacita_baterie * Soc_Kriticke), C98 - D98 + P98)) -> 0.559 | O98: =N98 / Účinnost_cyklu -> 0.62111111 | P98: =Vlastní_Spotřeba_kWh -> 0.01825
A99: Σ | B99: / | C99: =SUM(C3:C98) -> 67.7985 | D99: =SUM(D3:D98) -> 1.9405 | E99: =SUM(E3:E98) -> 21.309 | F99: =SUM(F3:F98) -> 16.098223 | G99: =SUM(G3:G98) -> 1.9992195 | H99: =SUM(H3:H98) -> 49.759777 | I99: =SUM(I3:I98) -> -46.4895 | J99: =J98 -> 1.562 | K99: =K98 -> 0.0781 | L99: =SUM(L3:L98) -> 15.632352 | M99: =SUM(M3:M98) -> 17.369281 | N99: =SUM(N3:N98) -> 51.194527 | O99: =SUM(O3:O98) -> 56.882808 | P99: =SUM(P3:P98) -> 1.752
D102: =F99+H99+D99 -> 67.7985 | J102: max | K102: =MAX(J3:J98) -> 18 | L102: Kwh
J103: min | K103: =MIN(J3:J98) -> 1.54375
J104: rozdil 24h | K104: =J98 -J2 -> -8.438
J105: DoD | K105: =MAX(J3:J98) - MIN(J3:J98) -> 16.45625
D108: Mobilní telefon | E108: =SUM(OFFSET('Leden data'!$D$2:$D$97, 0, ROW(A1)-1)) -> 45 | F108: Kwh
D109: Notebook | E109: =SUM(OFFSET('Leden data'!$D$2:$D$97, 0, ROW(A2)-1)) -> 0.03375
D110: Sušička | E110: =SUM(OFFSET('Leden data'!$D$2:$D$97, 0, ROW(A3)-1)) -> 0.3
D111: Elektrický sporák | E111: =SUM(OFFSET('Leden data'!$D$2:$D$97, 0, ROW(A4)-1)) -> 9
D112: Tablet | E112: =SUM(OFFSET('Leden data'!$D$2:$D$97, 0, ROW(A5)-1)) -> 0.375
D113: Kávovar | E113: =SUM(OFFSET('Leden data'!$D$2:$D$97, 0, ROW(A6)-1)) -> 4.5
D114: Elektrické žaluzie | E114: =SUM(OFFSET('Leden data'!$D$2:$D$97, 0, ROW(A7)-1)) -> 0.36125
D115: Pračka | E115: =SUM(OFFSET('Leden data'!$D$2:$D$97, 0, ROW(A8)-1)) -> 0.8125
D116: Vysavač | E116: =SUM(OFFSET('Leden data'!$D$2:$D$97, 0, ROW(A9)-1)) -> 0
D117: Elektrická trouba | E117: =SUM(OFFSET('Leden data'!$D$2:$D$97, 0, ROW(A10)-1)) -> 0
D118: Mikrovlnka | E118: =SUM(OFFSET('Leden data'!$D$2:$D$97, 0, ROW(A11)-1)) -> 3.85
D119: Počítače | E119: =SUM(OFFSET('Leden data'!$D$2:$D$97, 0, ROW(A12)-1)) -> 0.389
D120: Radio | E120: =SUM(OFFSET('Leden data'!$D$2:$D$97, 0, ROW(A13)-1)) -> 0.125
... D125: Plynový kotel + ohřev vody + topení | E125: =SUM(OFFSET('Leden data'!$D$2:$D$97, 0, ROW(A18)-1)) -> 0.03

Sheet Leden data
A1: Datum | B1: Čas | C1: klidové spotřeby domu | D1: Plynový kotel + ohřev vody + topení | E1: Tablet | F1: Mobilní telefon | G1: Elektrický sporák | H1: Mikrovlnka | I1: Elektrická trouba | J1: Televize | K1: Počítače | L1: Pračka | M1: Sušička | N1: Myčka | O1: Osvětlení | P1: Radio | Q1: Elektrické žaluzie | R1: Kávovar | S1: Notebook | T1: Topinkovač | U1: Vysavač | V1: Spotřeba domácnosti
A2: 46023 | B2: 0:00h | C2: 0.0075 | D2: 0.5 | E2: 0.00375 | F2: 0.015 | G2: 0 | H2: 0 | I2: 0 | J2: 0 | K2: 0 | L2: 0 | M2: 0 | N2: 0 | O2: 0 | P2: 0 | Q2: 0 | R2: 0 | S2: 0 | T2: 0 | U2: 0 | V2: =C2+D2+E2+F2+G2+H2+I2+J2+K2+L2+M2+N2+O2+P2+Q2+R2+S2+T2+U2 -> 0.52625
A3: 46023 | B3: 0:15h | C3: 0.0075 | D3: 0.5 | E3: 0.00375 | F3: 0.015 | G3: 0 | H3: 0 | I3: 0 | J3: 0 | K3: 0 | L3: 0 | M3: 0 | N3: 0 | O3: 0 | P3: 0 | Q3: 0 | R3: 0 | S3: 0 | T3: 0 | U3: 0 | V3: =C3+D3+E3+F3+G3+H3+I3+J3+K3+L3+M3+N3+O3+P3+Q3+R3+S3+T3+U3 -> 0.52625
A4: 46023 | B4: 0:30h | C4: 0.0075 | D4: 0.5 | E4: 0.00375 | F4: 0.015 | G4: 0 | H4: 0 | I4: 0 | J4: 0 | K4: 0 | L4: 0 | M4: 0 | N4: 0 | O4: 0 | P4: 0 | Q4: 0 | R4: 0 | S4: 0 | T4: 0 | U4: 0 | V4: =C4+D4+E4+F4+G4+H4+I4+J4+K4+L4+M4+N4+O4+P4+Q4+R4+S4+T4+U4 -> 0.52625
A5: 46023 | B5: 0:45h | C5: 0.0075 | D5: 0.5 | E5: 0.00375 | F5: 0.015 | G5: 0 | H5: 0 | I5: 0 | J5: 0 | K5: 0 | L5: 0 | M5: 0 | N5: 0 | O5: 0 | P5: 0 | Q5: 0 | R5: 0 | S5: 0 | T5: 0 | U5: 0 | V5: =C5+D5+E5+F5+G5+H5+I5+J5+K5+L5+M5+N5+O5+P5+Q5+R5+S5+T5+U5 -> 0.52625
A6: 46023 | B6: 1:00h | C6: 0.0075 | D6: 0.5 | E6: 0.00375 | F6: 0.015 | G6: 0 | H6: 0 | I6: 0 | J6: 0 | K6: 0 | L6: 0 | M6: 0 | N6: 0 | O6: 0 | P6: 0 | Q6: 0 | R6: 0 | S6: 0 | T6: 0 | U6: 0 | V6: =C6+D6+E6+F6+G6+H6+I6+J6+K6+L6+M6+N6+O6+P6+Q6+R6+S6+T6+U6 -> 0.52625
A7: 46023 | B7: 1:15h | C7: 0.0075 | D7: 0.5 | E7: 0.00375 | F7: 0.015 | G7: 0 | H7: 0 | I7: 0 | J7: 0 | K7: 0 | L7: 0 | M7: 0 | N7: 0 | O7: 0 | P7: 0 | Q7: 0 | R7: 0 | S7: 0 | T7: 0 | U7: 0 | V7: =C7+D7+E7+F7+G7+H7+I7+J7+K7+L7+M7+N7+O7+P7+Q7+R7+S7+T7+U7 -> 0.52625
A8: 46023 | B8: 1:30h | C8: 0.0075 | D8: 0.5 | E8: 0.00375 | F8: 0.015 | G8: 0 | H8: 0 | I8: 0 | J8: 0 | K8: 0 | L8: 0 | M8: 0 | N8: 0 | O8: 0 | P8: 0 | Q8: 0 | R8: 0 | S8: 0 | T8: 0 | U8: 0 | V8: =C8+D8+E8+F8+G8+H8+I8+J8+K8+L8+M8+N8+O8+P8+Q8+R8+S8+T8+U8 -> 0.52625
A9: 46023 | B9: 1:45h | C9: 0.0075 | D9: 0.5 | E9: 0.00375 | F9: 0.015 | G9: 0 | H9: 0 | I9: 0 | J9: 0 | K9: 0 | L9: 0 | M9: 0 | N9: 0 | O9: 0 | P9: 0 | Q9: 0 | R9: 0 | S9: 0 | T9: 0 | U9: 0 | V9: =C9+D9+E9+F9+G9+H9+I9+J9+K9+L9+M9+N9+O9+P9+Q9+R9+S9+T9+U9 -> 0.52625
A10: 46023 | B10: 2:00h | C10: 0.0075 | D10: 0.5 | E10: 0.00375 | F10: 0.015 | G10: 0 | H10: 0 | I10: 0 | J10: 0 | K10: 0 | L10: 0 | M10: 0 | N10: 0 | O10: 0 | P10: 0 | Q10: 0 | R10: 0 | S10: 0 | T10: 0 | U10: 0 | V10: =C10+D10+E10+F10+G10+H10+I10+J10+K10+L10+M10+N10+O10+P10+Q10+R10+S10+T10+U10 -> 0.52625
A11: 46023 | B11: 2:15h | C11: 0.0075 | D11: 0.5 | E11: 0 | F11: 0 | G11: 0 | H11: 0 | I11: 0 | J11: 0 | K11: 0 | L11: 0 | M11: 0 | N11: 0 | O11: 0 | P11: 0 | Q11: 0 | R11: 0 | S11: 0 | T11: 0 | U11: 0 | V11: =C11+D11+E11+F11+G11+H11+I11+J11+K11+L11+M11+N11+O11+P11+Q11+R11+S11+T11+U11 -> 0.5075
A12: 46023 | B12: 2:30h | C12: 0.0075 | D12: 0.5 | E12: 0 | F12: 0 | G12: 0 | H12: 0 | I12: 0 | J12: 0 | K12: 0 | L12: 0 | M12: 0 | N12: 0 | O12: 0 | P12: 0 | Q12: 0 | R12: 0 | S12: 0 | T12: 0 | U12: 0 | V12: =C12+D12+E12+F12+G12+H12+I12+J12+K12+L12+M12+N12+O12+P12+Q12+R12+S12+T12+U12 -> 0.5075
A13: 46023 | B13: 2:45h | C13: 0.0075 | D13: 0.5 | E13: 0 | F13: 0 | G13: 0 | H13: 0 | I13: 0 | J13: 0 | K13: 0 | L13: 0 | M13: 0 | N13: 0 | O13: 0 | P13: 0 | Q13: 0 | R13: 0 | S13: 0 | T13: 0 | U13: 0 | V13: =C13+D13+E13+F13+G13+H13+I13+J13+K13+L13+M13+N13+O13+P13+Q13+R13+S13+T13+U13 -> 0.5075
... A97: 46023 | B97: 23:45h | C97: 0.0075 | D97: 0.5 | E97: 0 | F97: 0.015 | G97: 0 | H97: 0 | I97: 0 | J97: 0 | K97: 0 | L97: 0 | M97: 0 | N97: 0 | O97: 0 | P97: 0 | Q97: 0 | R97: 0 | S97: 0 | T97: 0 | U97: 0 | V97: =C97+D97+E97+F97+G97+H97+I97+J97+K97+L97+M97+N97+O97+P97+Q97+R97+S97+T97+U97 -> 0.5225
C98: =SUM(C2:C97) -> 0.72 | D98: =SUM(D2:D97) -> 45 | F98: =SUM(F2:F97) -> 0.3 | G98: =SUM(G2:G97) -> 9 | H98: =SUM(H2:H97) -> 0.375 | I98: =SUM(I2:I97) -> 4.5 | J98: =SUM(J2:J97) -> 0.36125 | K98: =SUM(K2:K97) -> 0.8125 | L98: =SUM(L2:L97) -> 0 | M98: =SUM(M2:M97) -> 0 | ... V98: =SUM(V2:V97) -> 66.0465
C106: klidová spotřeba
C107: Plynový kotel + ohřev vody + topení | D107: W | K107: Plynový kotel + ohřev vody + topení | O107: Plynový kotel + ohřev vody + topení
B108: 13 | C108: Led osvětlení | D108: 90 | E108: 90. 0,25 | F108: 22.5 | G108: 0.0225 | I108: v | K108: Tablet | O108: Tablet
B109: 3 | C109: Mobilni telefony | D109: 60 | E109: 60.0,25 | F109: 15 | G109: 0.015 | I109: v | K109: Mobilní telefon | O109: Mobilní telefon
B110: 1 | C110: Tablet | D110: 15 | E110: 15.0,25 | F110: 3.75 | G110: 0.00375 | I110: v | K110: Elektrický sporák | O110: Elektrický sporák
B111: 2 | C111: Radio | D111: 20 | E111: 20.0,25 | F111: 5 | G111: 0.005 | I111: v | K111: Mikrovlnka | O111: Mikrovlnka
C112: Elektrické žaluzie | D112: 200 | E112: 200.0,25 | F112: 50 | G112: 0.05 | I112: v | K112: Elektrická trouba | O112: Elektrická trouba
B113: 1 | C113: Televize | D113: 85 | E113: 85.0,25 | F113: 21.25 | G113: 0.02125 | I113: v | K113: Sušička | O113: Televize
B114: 1 | C114: Počítač HAL300 | D114: 250 | E114: 250.0,25 | F114: 62.5 | G114: 0.0625 | I114: v | K114: Myčka | O114: Počítače
B115: 1 | C115: Notebook | D115: 100 | E115: 100.0,25 | F115: 25 | G115: 0.025 | I115: v | K115: Osvětlení | O115: Pračka
B116: 1 | C116: Kávovár | D116: 1300 | E116: 1300.0,25 | F116: 325 | G116: 0.325 | I116: v | K116: Radio | O116: Sušička
B117: 1 | C117: Topinkovač WMF | D117: 800 | E117: 800.0,25 | F117: 160 | G117: 0.16 | K117: Elektrické žaluzie | O117: Myčka
B118: 1 | C118: Mikrovlnka Whirlpool | D118: 1500 | E118: 1500.0,25 | F118: 375 | G118: 0.375 | K118: Kávovar | O118: Osvětlení
B119: 1 | C119: Chladnička Siemens | D119: 120 | E119: 120.0,25 | F119: 30 | G119: 0.03 | K119: Notebook | O119: Radio
B120: 1 | C120: Trouba Gorenje | D120: 3000 | E120: 3000.0,25 | F120: 750 | G120: 0.75 | K120: Topinkovač | O120: Elektrické žaluzie
B121: 1 | C121: Elektrický sporák | D121: 6000 | E121: 6000.0,25 | F121: 1500 | G121: 1 polt. 1,500 | H121: 1.5 | K121: Vysavač | O121: Kávovar
B122: 1 | C122: Myčka | D122: 2200 | E122: 2200.0,25 | F122: 550 | H122: 0.55 | I122: v | O122: Notebook
B123: 1 | C123: Pračka | D123: 2100 | E123: 2100.0,25 | F123: 525 | H123: 0.525 | I123: v | O123: Topinkovač
B124: 1 | C124: Sušička | D124: 1500 | E124: 1500.0,25 | F124: 375 | H124: 0.375 | O124: Vysavač
B125: 1 | C125: vysavač F | D125: 30 | E125: 30.0,25 | F125: 7.5 | H125: 0.0075
B126: 1 | C126: vysavač R | D126: 1000 | E126: 1000.0,25 | F126: 250 | H126: 0.25

Sheet Leden vík
A1: Datum | B1: Čas | C1: Spotřeba | D1: Přímá vlastní spotřeba z FVE | E1: Výroba FVE | F1: Odběr z DS | G1: Přetok do DS | H1: Spotřeba z baterie | I1: Bilance | J1: Stav baterie | K1: Soc | L1: Nabíjení (Netto) | M1: Nabíjení (Brutto) | N1: Vybíjení (Netto) | O1: Vybíjení (Brutto) | P1: Vlastní spotřeba
C2: kWh | D2: kwh | E2: kWh | F2: kWh | G2: kWh | H2: kWh | I2: kWh | J2: 7 | K2: % | L2: kWh | M2: kWh | N2: kWh | O2: kWh | P2: kWh
A3: =DATE(2026,1,2) -> 46024 | B3: =TIME(0,0,0) -> 0 | C3: ='Leden vík data'!V2+P3 -> 0.54575 | D3: =MIN(C3, E3) -> 0 | E3: =ROUND(MAX(0, 6.9 * EXP(-((HOUR(B3)+MINUTE(B3)/60 - 12)^2) / 2) * 0.25), 3) -> 0 | F3: =MAX(0, C3 - D3 - H3 ) -> 0 | G3: =MAX(0, E3 - D3 - M3) -> 0 | H3: =MAX(0, MIN(C3 - D3, N3 )) -> 0.54575 | I3: =E3-C3 -> -0.54575 | J3: =MIN('Výpočty '!$B$1*0.9, MAX('Výpočty '!$B$1*0.05, J2 + M3 - MIN(O3, MAX(0, J2 - ('Výpočty '!$B$1*0.1))) - P3)) -> 6.3550833 | K3: =J3/'Výpočty '!$B$1 -> 0.31775417 | L3: =M3 * Účinnost_cyklu -> 0 | M3: =MIN(MAX(0, I3), MAX(0, Kapacita_baterie * Soc_Max - J2) / Účinnost_cyklu, Stridac_limit) -> 0 | N3: =MAX(0, MIN(J2 - (Kapacita_baterie * Soc_Kriticke), C3 - D3 + P3)) -> 0.564 | O3: =N3 / Účinnost_cyklu -> 0.62666667 | P3: =Vlastní_Spotřeba_kWh -> 0.01825
A4: =DATE(2026,1,2) -> 46024 | B4: =B3+TIME(0,15,0) -> 0.010416667 | C4: ='Leden vík data'!V3+P4 -> 0.54575 | D4: =MIN(C4, E4) -> 0 | E4: =ROUND(MAX(0, 6.9 * EXP(-((HOUR(B4)+MINUTE(B4)/60 - 12)^2) / 2) * 0.25), 3) -> 0 | F4: =MAX(0, C4 - D4 - H4 ) -> 0 | G4: =MAX(0, E4 - D4 - M4) -> 0 | H4: =MAX(0, MIN(C4 - D4, N4 )) -> 0.54575 | I4: =E4-C4 -> -0.54575 | J4: =MIN('Výpočty '!$B$1*0.9, MAX('Výpočty '!$B$1*0.05, J3 + M4 - MIN(O4, MAX(0, J3 - ('Výpočty '!$B$1*0.1))) - P4)) -> 5.7101667 | K4: =J4/'Výpočty '!$B$1 -> 0.28550833 | L4: =M4 * Účinnost_cyklu -> 0 | M4: =MIN(MAX(0, I4), MAX(0, Kapacita_baterie * Soc_Max - J3) / Účinnost_cyklu, Stridac_limit) -> 0 | N4: =MAX(0, MIN(J3 - (Kapacita_baterie * Soc_Kriticke), C4 - D4 + P4)) -> 0.564 | O4: =N4 / Účinnost_cyklu -> 0.62666667 | P4: =Vlastní_Spotřeba_kWh -> 0.01825
A5: =DATE(2026,1,2) -> 46024 | B5: =B4+TIME(0,15,0) -> 0.020833333 | C5: ='Leden vík data'!V4+P5 -> 0.54575 | D5: =MIN(C5, E5) -> 0 | E5: =ROUND(MAX(0, 6.9 * EXP(-((HOUR(B5)+MINUTE(B5)/60 - 12)^2) / 2) * 0.25), 3) -> 0 | F5: =MAX(0, C5 - D5 - H5 ) -> 0 | G5: =MAX(0, E5 - D5 - M5) -> 0 | H5: =MAX(0, MIN(C5 - D5, N5 )) -> 0.54575 | I5: =E5-C5 -> -0.54575 | J5: =MIN('Výpočty '!$B$1*0.9, MAX('Výpočty '!$B$1*0.05, J4 + M5 - MIN(O5, MAX(0, J4 - ('Výpočty '!$B$1*0.1))) - P5)) -> 5.06525 | K5: =J5/'Výpočty '!$B$1 -> 0.2532625 | L5: =M5 * Účinnost_cyklu -> 0 | M5: =MIN(MAX(0, I5), MAX(0, Kapacita_baterie * Soc_Max - J4) / Účinnost_cyklu, Stridac_limit) -> 0 | N5: =MAX(0, MIN(J4 - (Kapacita_baterie * Soc_Kriticke), C5 - D5 + P5)) -> 0.564 | O5: =N5 / Účinnost_cyklu -> 0.62666667 | P5: =Vlastní_Spotřeba_kWh -> 0.01825
A6: =DATE(2026,1,2) -> 46024 | B6: =B5+TIME(0,15,0) -> 0.03125 | C6: ='Leden vík data'!V5+P6 -> 0.54575 | D6: =MIN(C6, E6) -> 0 | E6: =ROUND(MAX(0, 6.9 * EXP(-((HOUR(B6)+MINUTE(B6)/60 - 12)^2) / 2) * 0.25), 3) -> 0 | F6: =MAX(0, C6 - D6 - H6 ) -> 0 | G6: =MAX(0, E6 - D6 - M6) -> 0 | H6: =MAX(0, MIN(C6 - D6, N6 )) -> 0.54575 | I6: =E6-C6 -> -0.54575 | J6: =MIN('Výpočty '!$B$1*0.9, MAX('Výpočty '!$B$1*0.05, J5 + M6 - MIN(O6, MAX(0, J5 - ('Výpočty '!$B$1*0.1))) - P6)) -> 4.4203333 | K6: =J6/'Výpočty '!$B$1 -> 0.22101667 | L6: =M6 * Účinnost_cyklu -> 0 | M6: =MIN(MAX(0, I6), MAX(0, Kapacita_baterie * Soc_Max - J5) / Účinnost_cyklu, Stridac_limit) -> 0 | N6: =MAX(0, MIN(J5 - (Kapacita_baterie * Soc_Kriticke), C6 - D6 + P6)) -> 0.564 | O6: =N6 / Účinnost_cyklu -> 0.62666667 | P6: =Vlastní_Spotřeba_kWh -> 0.01825
A7: =DATE(2026,1,2) -> 46024 | B7: =B6+TIME(0,15,0) -> 0.041666667 | C7: ='Leden vík data'!V6+P7 -> 0.54575 | D7: =MIN(C7, E7) -> 0 | E7: =ROUND(MAX(0, 6.9 * EXP(-((HOUR(B7)+MINUTE(B7)/60 - 12)^2) / 2) * 0.25), 3) -> 0 | F7: =MAX(0, C7 - D7 - H7 ) -> 0 | G7: =MAX(0, E7 - D7 - M7) -> 0 | H7: =MAX(0, MIN(C7 - D7, N7 )) -> 0.54575 | I7: =E7-C7 -> -0.54575 | J7: =MIN('Výpočty '!$B$1*0.9, MAX('Výpočty '!$B$1*0.05, J6 + M7 - MIN(O7, MAX(0, J6 - ('Výpočty '!$B$1*0.1))) - P7)) -> 3.7754167 | K7: =J7/'Výpočty '!$B$1 -> 0.18877083 | L7: =M7 * Účinnost_cyklu -> 0 | M7: =MIN(MAX(0, I7), MAX(0, Kapacita_baterie * Soc_Max - J6) / Účinnost_cyklu, Stridac_limit) -> 0 | N7: =MAX(0, MIN(J6 - (Kapacita_baterie * Soc_Kriticke), C7 - D7 + P7)) -> 0.564 | O7: =N7 / Účinnost_cyklu -> 0.62666667 | P7: =Vlastní_Spotřeba_kWh -> 0.01825
A8: =DATE(2026,1,2) -> 46024 | B8: =B7+TIME(0,15,0) -> 0.052083333 | C8: ='Leden vík data'!V7+P8 -> 0.54575 | D8: =MIN(C8, E8) -> 0 | E8: =ROUND(MAX(0, 6.9 * EXP(-((HOUR(B8)+MINUTE(B8)/60 - 12)^2) / 2) * 0.25), 3) -> 0 | F8: =MAX(0, C8 - D8 - H8 ) -> 0 | G8: =MAX(0, E8 - D8 - M8) -> 0 | H8: =MAX(0, MIN(C8 - D8, N8 )) -> 0.54575 | I8: =E8-C8 -> -0.54575 | J8: =MIN('Výpočty '!$B$1*0.9, MAX('Výpočty '!$B$1*0.05, J7 + M8 - MIN(O8, MAX(0, J7 - ('Výpočty '!$B$1*0.1))) - P8)) -> 3.1305 | K8: =J8/'Výpočty '!$B$1 -> 0.156525 | L8: =M8 * Účinnost_cyklu -> 0 | M8: =MIN(MAX(0, I8), MAX(0, Kapacita_baterie * Soc_Max - J7) / Účinnost_cyklu, Stridac_limit) -> 0 | N8: =MAX(0, MIN(J7 - (Kapacita_baterie * Soc_Kriticke), C8 - D8 + P8)) -> 0.564 | O8: =N8 / Účinnost_cyklu -> 0.62666667 | P8: =Vlastní_Spotřeba_kWh -> 0.01825
A9: =DATE(2026,1,2) -> 46024 | B9: =B8+TIME(0,15,0) -> 0.0625 | C9: ='Leden vík data'!V8+P9 -> 0.54575 | D9: =MIN(C9, E9) -> 0 | E9: =ROUND(MAX(0, 6.9 * EXP(-((HOUR(B9)+MINUTE(B9)/60 - 12)^2) / 2) * 0.25), 3) -> 0 | F9: =MAX(0, C9 - D9 - H9 ) -> 0 | G9: =MAX(0, E9 - D9 - M9) -> 0 | H9: =MAX(0, MIN(C9 - D9, N9 )) -> 0.54575 | I9: =E9-C9 -> -0.54575 | J9: =MIN('Výpočty '!$B$1*0.9, MAX('Výpočty '!$B$1*0.05, J8 + M9 - MIN(O9, MAX(0, J8 - ('Výpočty '!$B$1*0.1))) - P9)) -> 2.4855833 | K9: =J9/'Výpočty '!$B$1 -> 0.12427917 | L9: =M9 * Účinnost_cyklu -> 0 | M9: =MIN(MAX(0, I9), MAX(0, Kapacita_baterie * Soc_Max - J8) / Účinnost_cyklu, Stridac_limit) -> 0 | N9: =MAX(0, MIN(J8 - (Kapacita_baterie * Soc_Kriticke), C9 - D9 + P9)) -> 0.564 | O9: =N9 / Účinnost_cyklu -> 0.62666667 | P9: =Vlastní_Spotřeba_kWh -> 0.01825
A10: =DATE(2026,1,2) -> 46024 | B10: =B9+TIME(0,15,0) -> 0.072916667 | C10: ='Leden vík data'!V9+P10 -> 0.54075 | D10: =MIN(C10, E10) -> 0 | E10: =ROUND(MAX(0, 6.9 * EXP(-((HOUR(B10)+MINUTE(B10)/60 - 12)^2) / 2) * 0.25), 3) -> 0 | F10: =MAX(0, C10 - D10 - H10 ) -> 0 | G10: =MAX(0, E10 - D10 - M10) -> 0 | H10: =MAX(0, MIN(C10 - D10, N10 )) -> 0.54075 | I10: =E10-C10 -> -0.54075 | J10: =MIN('Výpočty '!$B$1*0.9, MAX('Výpočty '!$B$1*0.05, J9 + M10 - MIN(O10, MAX(0, J9 - ('Výpočty '!$B$1*0.1))) - P10)) -> 1.98175 | K10: =J10/'Výpočty '!$B$1 -> 0.0990875 | L10: =M10 * Účinnost_cyklu -> 0 | M10: =MIN(MAX(0, I10), MAX(0, Kapacita_baterie * Soc_Max - J9) / Účinnost_cyklu, Stridac_limit) -> 0 | N10: =MAX(0, MIN(J9 - (Kapacita_baterie * Soc_Kriticke), C10 - D10 + P10)) -> 0.559 | O10: =N10 / Účinnost_cyklu -> 0.62111111 | P10: =Vlastní_Spotřeba_kWh -> 0.01825
A11: =DATE(2026,1,2) -> 46024 | B11: =B10+TIME(0,15,0) -> 0.083333333 | C11: ='Leden vík data'!V10+P11 -> 0.54075 | D11: =MIN(C11, E11) -> 0 | E11: =ROUND(MAX(0, 6.9 * EXP(-((HOUR(B11)+MINUTE(B11)/60 - 12)^2) / 2) * 0.25), 3) -> 0 | F11: =MAX(0, C11 - D11 - H11 ) -> 0 | G11: =MAX(0, E11 - D11 - M11) -> 0 | H11: =MAX(0, MIN(C11 - D11, N11 )) -> 0.54075 | I11: =E11-C11 -> -0.54075 | J11: =MIN('Výpočty '!$B$1*0.9, MAX('Výpočty '!$B$1*0.05, J10 + M11 - MIN(O11, MAX(0, J10 - ('Výpočty '!$B$1*0.1))) - P11)) -> 1.9635 | K11: =J11/'Výpočty '!$B$1 -> 0.098175 | L11: =M11 * Účinnost_cyklu -> 0 | M11: =MIN(MAX(0, I11), MAX(0, Kapacita_baterie * Soc_Max - J10) / Účinnost_cyklu, Stridac_limit) -> 0 | N11: =MAX(0, MIN(J10 - (Kapacita_baterie * Soc_Kriticke), C11 - D11 + P11)) -> 0.559 | O11: =N11 / Účinnost_cyklu -> 0.62111111 | P11: =Vlastní_Spotřeba_kWh -> 0.01825
A12: =DATE(2026,1,2) -> 46024 | B12: =B11+TIME(0,15,0) -> 0.09375 | C12: ='Leden vík data'!V11+P12 -> 0.52575 | D12: =MIN(C12, E12) -> 0 | E12: =ROUND(MAX(0, 6.9 * EXP(-((HOUR(B12)+MINUTE(B12)/60 - 12)^2) / 2) * 0.25), 3) -> 0 | F12: =MAX(0, C12 - D12 - H12 ) -> 0 | G12: =MAX(0, E12 - D12 - M12) -> 0 | H12: =MAX(0, MIN(C12 - D12, N12 )) -> 0.52575 | I12: =E12-C12 -> -0.52575 | J12: =MIN('Výpočty '!$B$1*0.9, MAX('Výpočty '!$B$1*0.05, J11 + M12 - MIN(O12, MAX(0, J11 - ('Výpočty '!$B$1*0.1))) - P12)) -> 1.94525 | K12: =J12/'Výpočty '!$B$1 -> 0.0972625 | L12: =M12 * Účinnost_cyklu -> 0 | M12: =MIN(MAX(0, I12), MAX(0, Kapacita_baterie * Soc_Max - J11) / Účinnost_cyklu, Stridac_limit) -> 0 | N12: =MAX(0, MIN(J11 - (Kapacita_baterie * Soc_Kriticke), C12 - D12 + P12)) -> 0.544 | O12: =N12 / Účinnost_cyklu -> 0.60444444 | P12: =Vlastní_Spotřeba_kWh -> 0.01825
A13: =DATE(2026,1,2) -> 46024 | B13: =B12+TIME(0,15,0) -> 0.10416667 | C13: ='Leden vík data'!V12+P13 -> 0.52575 | D13: =MIN(C13, E13) -> 0 | E13: =ROUND(MAX(0, 6.9 * EXP(-((HOUR(B13)+MINUTE(B13)/60 - 12)^2) / 2) * 0.25), 3) -> 0 | F13: =MAX(0, C13 - D13 - H13 ) -> 0 | G13: =MAX(0, E13 - D13 - M13) -> 0 | H13: =MAX(0, MIN(C13 - D13, N13 )) -> 0.52575 | I13: =E13-C13 -> -0.52575 | J13: =MIN('Výpočty '!$B$1*0.9, MAX('Výpočty '!$B$1*0.05, J12 + M13 - MIN(O13, MAX(0, J12 - ('Výpočty '!$B$1*0.1))) - P13)) -> 1.927 | K13: =J13/'Výpočty '!$B$1 -> 0.09635 | L13: =M13 * Účinnost_cyklu -> 0 | M13: =MIN(MAX(0, I13), MAX(0, Kapacita_baterie * Soc_Max - J12) / Účinnost_cyklu, Stridac_limit) -> 0 | N13: =MAX(0, MIN(J12 - (Kapacita_baterie * Soc_Kriticke), C13 - D13 + P13)) -> 0.544 | O13: =N13 / Účinnost_cyklu -> 0.60444444 | P13: =Vlastní_Spotřeba_kWh -> 0.01825
A14: =DATE(2026,1,2) -> 46024 | B14: =B13+TIME(0,15,0) -> 0.11458333 | C14: ='Leden vík data'!V13+P14 -> 0.52575 | D14: =MIN(C14, E14) -> 0 | E14: =ROUND(MAX(0, 6.9 * EXP(-((HOUR(B14)+MINUTE(B14)/60 - 12)^2) / 2) * 0.25), 3) -> 0 | F14: =MAX(0, C14 - D14 - H14 ) -> 0 | G14: =MAX(0, E14 - D14 - M14) -> 0 | H14: =MAX(0, MIN(C14 - D14, N14 )) -> 0.52575 | I14: =E14-C14 -> -0.52575 | J14: =MIN('Výpočty '!$B$1*0.9, MAX('Výpočty '!$B$1*0.05, J13 + M14 - MIN(O14, MAX(0, J13 - ('Výpočty '!$B$1*0.1))) - P14)) -> 1.90875 | K14: =J14/'Výpočty '!$B$1 -> 0.0954375 | L14: =M14 * Účinnost_cyklu -> 0 | M14: =MIN(MAX(0, I14), MAX(0, Kapacita_baterie * Soc_Max - J13) / Účinnost_cyklu, Stridac_limit) -> 0 | N14: =MAX(0, MIN(J13 - (Kapacita_baterie * Soc_Kriticke), C14 - D14 + P14)) -> 0.544 | O14: =N14 / Účinnost_cyklu -> 0.60444444 | P14: =Vlastní_Spotřeba_kWh -> 0.01825
A15: =DATE(2026,1,2) -> 46024 | B15: =B14+TIME(0,15,0) -> 0.125 | C15: ='Leden vík data'!V14+P15 -> 0.52575 | D15: =MIN(C15, E15) -> 0 | E15: =ROUND(MAX(0, 6.9 * EXP(-((HOUR(B15)+MINUTE(B15)/60 - 12)^2) / 2) * 0.25), 3) -> 0 | F15: =MAX(0, C15 - D15 - H15 ) -> 0 | G15: =MAX(0, E15 - D15 - M15) -> 0 | H15: =MAX(0, MIN(C15 - D15, N15 )) -> 0.52575 | I15: =E15-C15 -> -0.52575 | J15: =MIN('Výpočty '!$B$1*0.9, MAX('Výpočty '!$B$1*0.05, J14 + M15 - MIN(O15, MAX(0, J14 - ('Výpočty '!$B$1*0.1))) - P15)) -> 1.8905 | K15: =J15/'Výpočty '!$B$1 -> 0.094525 | L15: =M15 * Účinnost_cyklu -> 0 | M15: =MIN(MAX(0, I15), MAX(0, Kapacita_baterie * Soc_Max - J14) / Účinnost_cyklu, Stridac_limit) -> 0 | N15: =MAX(0, MIN(J14 - (Kapacita_baterie * Soc_Kriticke), C15 - D15 + P15)) -> 0.544 | O15: =N15 / Účinnost_cyklu -> 0.60444444 | P15: =Vlastní_Spotřeba_kWh -> 0.01825
... A98: =DATE(2026,1,2) -> 46024 | B98: =B97+TIME(0,15,0) -> 0.98958333 | C98: ='Leden vík data'!V97+P98 -> 0.567 | D98: =MIN(C98, E98) -> 0 | E98: =ROUND(MAX(0, 6.9 * EXP(-((HOUR(B98)+MINUTE(B98)/60 - 12)^2) / 2) * 0.25), 3) -> 0 | F98: =MAX(0, C98 - D98 - H98 ) -> 0.567 | G98: =MAX(0, E98 - D98 - M98) -> 0 | H98: =MAX(0, MIN(C98 - D98, N98 )) -> 0 | I98: =E98-C98 -> -0.567 | J98: =MIN('Výpočty '!$B$1*0.9, MAX('Výpočty '!$B$1*0.05, J97 + M98 - MIN(O98, MAX(0, J97 - ('Výpočty '!$B$1*0.1))) - P98)) -> 1 | K98: =J98/'Výpočty '!$B$1 -> 0.05 | L98: =M98 * Účinnost_cyklu -> 0 | M98: =MIN(MAX(0, I98), MAX(0, Kapacita_baterie * Soc_Max - J97) / Účinnost_cyklu, Stridac_limit) -> 0 | N98: =MAX(0, MIN(J97 - (Kapacita_baterie * Soc_Kriticke), C98 - D98 + P98)) -> 0 | O98: =N98 / Účinnost_cyklu -> 0 | P98: =Vlastní_Spotřeba_kWh -> 0.01825
A99: Σ | B99: / | C99: =SUM(C3:C98) -> 100.4415 | D99: =SUM(D3:D98) -> 17.295 | E99: =SUM(E3:E98) -> 17.295 | F99: =SUM(F3:F98) -> 58.16325 | G99: =SUM(G3:G98) -> 0 | H99: =SUM(H3:H98) -> 24.98325 | I99: =SUM(I3:I98) -> -83.1465 | J99: =J98 -> 1 | K99: =K98 -> 0.05 | L99: =SUM(L3:L98) -> 0 | M99: =SUM(M3:M98) -> 0 | N99: =SUM(N3:N98) -> 25.6125 | O99: =SUM(O3:O98) -> 28.458333 | P99: =SUM(P3:P98) -> 1.752
J102: max | K102: =MAX(J3:J98) -> 6.3550833 | L102: Kwh
J103: min | K103: =MIN(J3:J98) -> 1
J104: rozdil 24h | K104: =J98 -J2 -> -6
J105: DoD | K105: =MAX(J3:J98) - MIN(J3:J98) -> 5.3550833
D108: Plynový kotel + ohřev vody + topení | E108: =SUM(OFFSET('Leden vík data'!$D$2:$D$97, 0, ROW(A1)-1)) -> 65.5 | F108: Kwh
D109: Tablet | E109: =SUM(OFFSET('Leden vík data'!$D$2:$D$97, 0, ROW(A2)-1)) -> 0.03375
D110: Mobilní telefon | E110: =SUM(OFFSET('Leden vík data'!$D$2:$D$97, 0, ROW(A3)-1)) -> 0.255
D111: Elektrický sporák | E111: =SUM(OFFSET('Leden vík data'!$D$2:$D$97, 0, ROW(A4)-1)) -> 13.5
D112: Mikrovlnka | E112: =SUM(OFFSET('Leden vík data'!$D$2:$D$97, 0, ROW(A5)-1)) -> 0.375
D113: Elektrická trouba | E113: =SUM(OFFSET('Leden vík data'!$D$2:$D$97, 0, ROW(A6)-1)) -> 5.25
D114: Televize | E114: =SUM(OFFSET('Leden vík data'!$D$2:$D$97, 0, ROW(A7)-1)) -> 0.61625
D115: Počítače | E115: =SUM(OFFSET('Leden vík data'!$D$2:$D$97, 0, ROW(A8)-1)) -> 1.0625
D116: Pračka | E116: =SUM(OFFSET('Leden vík data'!$D$2:$D$97, 0, ROW(A9)-1)) -> 2.625
D117: Sušička | E117: =SUM(OFFSET('Leden vík data'!$D$2:$D$97, 0, ROW(A10)-1)) -> 1.5
D118: Myčka | E118: =SUM(OFFSET('Leden vík data'!$D$2:$D$97, 0, ROW(A11)-1)) -> 5.5
D119: Osvětlení | E119: =SUM(OFFSET('Leden vík data'!$D$2:$D$97, 0, ROW(A12)-1)) -> 0.542
D120: Radio | E120: =SUM(OFFSET('Leden vík data'!$D$2:$D$97, 0, ROW(A13)-1)) -> 0.32
... D125: Vysavač | E125: =SUM(OFFSET('Leden vík data'!$D$2:$D$97, 0, ROW(A18)-1)) -> 0

Sheet Leden vík data
A1: Datum | B1: Čas | C1: klidové spotřeby domu | D1: Plynový kotel + ohřev vody + topení | E1: Tablet | F1: Mobilní telefon | G1: Elektrický sporák | H1: Mikrovlnka | I1: Elektrická trouba | J1: Televize | K1: Počítače | L1: Pračka | M1: Sušička | N1: Myčka | O1: Osvětlení | P1: Radio | Q1: Elektrické žaluzie | R1: Kávovar | S1: Notebook | T1: Topinkovač | U1: Vysavač | V1: Spotřeba domácnosti
A2: 46024 | B2: 0:00h | C2: 0.0075 | D2: 0.5 | E2: 0 | F2: 0.015 | G2: 0 | H2: 0 | I2: 0 | J2: 0 | K2: 0 | L2: 0 | M2: 0 | N2: 0 | O2: 0.005 | P2: 0 | Q2: 0 | R2: 0 | S2: 0 | T2: 0 | U2: 0 | V2: =C2+D2+E2+F2+G2+H2+I2+J2+K2+L2+M2+N2+O2+P2+Q2+R2+S2+T2+U2 -> 0.5275
A3: 46024 | B3: 0:15h | C3: 0.0075 | D3: 0.5 | E3: 0 | F3: 0.015 | G3: 0 | H3: 0 | I3: 0 | J3: 0 | K3: 0 | L3: 0 | M3: 0 | N3: 0 | O3: 0.005 | P3: 0 | Q3: 0 | R3: 0 | S3: 0 | T3: 0 | U3: 0 | V3: =C3+D3+E3+F3+G3+H3+I3+J3+K3+L3+M3+N3+O3+P3+Q3+R3+S3+T3+U3 -> 0.5275
A4: 46024 | B4: 0:30h | C4: 0.0075 | D4: 0.5 | E4: 0 | F4: 0.015 | G4: 0 | H4: 0 | I4: 0 | J4: 0 | K4: 0 | L4: 0 | M4: 0 | N4: 0 | O4: 0.005 | P4: 0 | Q4: 0 | R4: 0 | S4: 0 | T4: 0 | U4: 0 | V4: =C4+D4+E4+F4+G4+H4+I4+J4+K4+L4+M4+N4+O4+P4+Q4+R4+S4+T4+U4 -> 0.5275
A5: 46024 | B5: 0:45h | C5: 0.0075 | D5: 0.5 | E5: 0 | F5: 0.015 | G5: 0 | H5: 0 | I5: 0 | J5: 0 | K5: 0 | L5: 0 | M5: 0 | N5: 0 | O5: 0.005 | P5: 0 | Q5: 0 | R5: 0 | S5: 0 | T5: 0 | U5: 0 | V5: =C5+D5+E5+F5+G5+H5+I5+J5+K5+L5+M5+N5+O5+P5+Q5+R5+S5+T5+U5 -> 0.5275
A6: 46024 | B6: 1:00h | C6: 0.0075 | D6: 0.5 | E6: 0 | F6: 0.015 | G6: 0 | H6: 0 | I6: 0 | J6: 0 | K6: 0 | L6: 0 | M6: 0 | N6: 0 | O6: 0.005 | P6: 0 | Q6: 0 | R6: 0 | S6: 0 | T6: 0 | U6: 0 | V6: =C6+D6+E6+F6+G6+H6+I6+J6+K6+L6+M6+N6+O6+P6+Q6+R6+S6+T6+U6 -> 0.5275
A7: 46024 | B7: 1:15h | C7: 0.0075 | D7: 0.5 | E7: 0 | F7: 0.015 | G7: 0 | H7: 0 | I7: 0 | J7: 0 | K7: 0 | L7: 0 | M7: 0 | N7: 0 | O7: 0.005 | P7: 0 | Q7: 0 | R7: 0 | S7: 0 | T7: 0 | U7: 0 | V7: =C7+D7+E7+F7+G7+H7+I7+J7+K7+L7+M7+N7+O7+P7+Q7+R7+S7+T7+U7 -> 0.5275
A8: 46024 | B8: 1:30h | C8: 0.0075 | D8: 0.5 | E8: 0 | F8: 0.015 | G8: 0 | H8: 0 | I8: 0 | J8: 0 | K8: 0 | L8: 0 | M8: 0 | N8: 0 | O8: 0.005 | P8: 0 | Q8: 0 | R8: 0 | S8: 0 | T8: 0 | U8: 0 | V8: =C8+D8+E8+F8+G8+H8+I8+J8+K8+L8+M8+N8+O8+P8+Q8+R8+S8+T8+U8 -> 0.5275
A9: 46024 | B9: 1:45h | C9: 0.0075 | D9: 0.5 | E9: 0 | F9: 0.015 | G9: 0 | H9: 0 | I9: 0 | J9: 0 | K9: 0 | L9: 0 | M9: 0 | N9: 0 | O9: 0 | P9: 0 | Q9: 0 | R9: 0 | S9: 0 | T9: 0 | U9: 0 | V9: =C9+D9+E9+F9+G9+H9+I9+J9+K9+L9+M9+N9+O9+P9+Q9+R9+S9+T9+U9 -> 0.5225
A10: 46024 | B10: 2:00h | C10: 0.0075 | D10: 0.5 | E10: 0 | F10: 0.015 | G10: 0 | H10: 0 | I10: 0 | J10: 0 | K10: 0 | L10: 0 | M10: 0 | N10: 0 | O10: 0 | P10: 0 | Q10: 0 | R10: 0 | S10: 0 | T10: 0 | U10: 0 | V10: =C10+D10+E10+F10+G10+H10+I10+J10+K10+L10+M10+N10+O10+P10+Q10+R10+S10+T10+U10 -> 0.5225
A11: 46024 | B11: 2:15h | C11: 0.0075 | D11: 0.5 | E11: 0 | F11: 0 | G11: 0 | H11: 0 | I11: 0 | J11: 0 | K11: 0 | L11: 0 | M11: 0 | N11: 0 | O11: 0 | P11: 0 | Q11: 0 | R11: 0 | S11: 0 | T11: 0 | U11: 0 | V11: =C11+D11+E11+F11+G11+H11+I11+J11+K11+L11+M11+N11+O11+P11+Q11+R11+S11+T11+U11 -> 0.5075
A12: 46024 | B12: 2:30h | C12: 0.0075 | D12: 0.5 | E12: 0 | F12: 0 | G12: 0 | H12: 0 | I12: 0 | J12: 0 | K12: 0 | L12: 0 | M12: 0 | N12: 0 | O12: 0 | P12: 0 | Q12: 0 | R12: 0 | S12: 0 | T12: 0 | U12: 0 | V12: =C12+D12+E12+F12+G12+H12+I12+J12+K12+L12+M12+N12+O12+P12+Q12+R12+S12+T12+U12 -> 0.5075
A13: 46024 | B13: 2:45h | C13: 0.0075 | D13: 0.5 | E13: 0 | F13: 0 | G13: 0 | H13: 0 | I13: 0 | J13: 0 | K13: 0 | L13: 0 | M13: 0 | N13: 0 | O13: 0 | P13: 0 | Q13: 0 | R13: 0 | S13: 0 | T13: 0 | U13: 0 | V13: =C13+D13+E13+F13+G13+H13+I13+J13+K13+L13+M13+N13+O13+P13+Q13+R13+S13+T13+U13 -> 0.5075
... A97: 46024 | B97: 23:45h | C97: 0.0075 | D97: 0.5 | E97: 0 | F97: 0.015 | G97: 0 | H97: 0 | I97: 0 | J97: 0.02125 | K97: 0 | L97: 0 | M97: 0 | N97: 0 | O97: 0.005 | P97: 0 | Q97: 0 | R97: 0 | S97: 0 | T97: 0 | U97: 0 | V97: =C97+D97+E97+F97+G97+H97+I97+J97+K97+L97+M97+N97+O97+P97+Q97+R97+S97+T97+U97 -> 0.54875
A98: 0 | B98: 0 | C98: 0 | D98: 0 | E98: 0 | F98: 0 | G98: 0 | H98: 0 | I98: 0 | J98: 0 | K98: 0 | L98: 0 | M98: 0 | N98: 0 | O98: 0 | P98: 0 | Q98: 0 | R98: 0 | S98: 0 | T98: 0 | U98: 0 | V98: =SUM(V2:V97) -> 98.6895
C106: klidová spotřeba
C107: Plynový kotel + ohřev vody + topení | D107: W
B108: 13 | C108: Led osvětlení | D108: 90 | E108: 90. 0,25 | F108: 22.5 | G108: 0.0225 | I108: v
B109: 3 | C109: Mobilni telefony | D109: 60 | E109: 60.0,25 | F109: 15 | G109: 0.015 | I109: v
B110: 1 | C110: Tablet | D110: 15 | E110: 15.0,25 | F110: 3.75 | G110: 0.00375 | I110: v
B111: 2 | C111: Radio | D111: 20 | E111: 20.0,25 | F111: 5 | G111: 0.005 | I111: v
C112: Elektrické žaluzie | D112: 200 | E112: 200.0,25 | F112: 50 | G112: 0.05 | I112: v
B113: 1 | C113: Televize | D113: 85 | E113: 85.0,25 | F113: 21.25 | G113: 0.02125 | I113: v
B114: 1 | C114: Počítač HAL300 | D114: 250 | E114: 250.0,25 | F114: 62.5 | G114: 0.0625 | I114: v
B115: 1 | C115: Notebook | D115: 100 | E115: 100.0,25 | F115: 25 | G115: 0.025 | I115: v
B116: 1 | C116: Kávovár | D116: 1300 | E116: 1300.0,25 | F116: 325 | G116: 0.325 | I116: v
B117: 1 | C117: Topinkovač WMF | D117: 800 | E117: 800.0,25 | F117: 160 | G117: 0.16
B118: 1 | C118: Mikrovlnka Whirlpool | D118: 1500 | E118: 1500.0,25 | F118: 375 | G118: 0.375
B119: 1 | C119: Chladnička Siemens | D119: 120 | E119: 120.0,25 | F119: 30 | G119: 0.03
B120: 1 | C120: Trouba Gorenje | D120: 3000 | E120: 3000.0,25 | F120: 750 | G120: 0.75
B121: 1 | C121: Elektrický sporák | D121: 6000 | E121: 6000.0,25 | F121: 1500 | G121: 1 polt. 1,500 | H121: 1.5
B122: 1 | C122: Myčka | D122: 2200 | E122: 2200.0,25 | F122: 550 | H122: 0.55 | I122: v
B123: 1 | C123: Pračka | D123: 2100 | E123: 2100.0,25 | F123: 525 | H123: 0.525 | I123: v
B124: 1 | C124: Sušička | D124: 1500 | E124: 1500.0,25 | F124: 375 | H124: 0.375
B125: 1 | C125: vysavač F | D125: 30 | E125: 30.0,25 | F125: 7.5 | H125: 0.0075
B126: 1 | C126: vysavač R | D126: 1000 | E126: 1000.0,25 | F126: 250 | H126: 0.25
C145: Plynový kotel + ohřev vody + topení
C146: Led osvětlení
C147: Mobilni telefony
C148: Tablet
...

Sheet Leden grafy

Sheet Leden kontig
A1: Popisky řádků | B1: Součet z Přímá vlastní spotřeba z FVE | C1: Součet z Výroba FVE | D1: Součet z Vybíjení (Netto) | E1: Součet z Odběr z DS | F1: Součet z Vybíjení (Brutto) | G1: Součet z Přetok do DS | H1: Součet z Spotřeba | I1: Součet z Spotřeba z baterie | J1: Součet z Bilance | K1: Počet z Stav baterie | L1: Součet z Soc | M1: Součet z Nabíjení (Netto) | N1: Součet z Nabíjení (Brutto) | O1: Součet z Vlastní spotřeba
A2: 46023 | B2: 1.9405 | C2: 21.309 | D2: 24.197003 | E2: 42.536997 | F2: 26.885559 | G2: 1.7852562 | H2: 67.7985 | I2: 23.321003 | J2: -46.4895 | K2: 96 | L2: 28.620811 | M2: 15.824919 | N2: 17.583244 | O2: 1.752
A3: I | B3: 1.9405 | C3: 21.309 | D3: 24.197003 | E3: 42.536997 | F3: 26.885559 | G3: 1.7852562 | H3: 67.7985 | I3: 23.321003 | J3: -46.4895 | K3: 96 | L3: 28.620811 | M3: 15.824919 | N3: 17.583244 | O3: 1.752
A4: 0 | B4: 0 | C4: 0 | D4: 2.251 | E4: 0 | F4: 2.5011111 | G4: 0 | H4: 2.178 | I4: 2.178 | J4: -2.178 | K4: 4 | L4: 2.0021127 | M4: 0 | N4: 0 | O4: 0.073
A5: 1 | B5: 0 | C5: 0 | D5: 2.251 | E5: 0 | F5: 2.5011111 | G5: 0 | H5: 2.178 | I5: 2.178 | J5: -2.178 | K5: 4 | L5: 1.4430408 | M5: 0 | N5: 0 | O5: 0.073
A6: 2 | B6: 0 | C6: 0 | D6: 2.19475 | E6: 0 | F6: 2.4386111 | G6: 0 | H6: 2.12175 | I6: 2.12175 | J6: -2.12175 | K6: 4 | L6: 0.8874616 | M6: 0 | N6: 0 | O6: 0.073
A7: 3 | B7: 0 | C7: 0 | D7: 1.4382778 | E7: 0.70122222 | F7: 1.5980864 | G7: 0 | H7: 2.103 | I7: 1.4017778 | J7: -2.103 | K7: 4 | L7: 0.36005637 | M7: 0 | N7: 0 | O7: 0.073
A8: 4 | B8: 0 | C8: 0 | D8: 0 | E8: 2.103 | F8: 0 | G8: 0 | H8: 2.103 | I8: 0 | J8: -2.103 | K8: 4 | L8: 0.2 | M8: 0 | N8: 0 | O8: 0.073
A9: 5 | B9: 0 | C9: 0 | D9: 0 | E9: 2.108 | F9: 0 | G9: 0 | H9: 2.108 | I9: 0 | J9: -2.108 | K9: 4 | L9: 0.2 | M9: 0 | N9: 0 | O9: 0.073
A10: 6 | B10: 0 | C10: 0 | D10: 0 | E10: 4.7215 | F10: 0 | G10: 0 | H10: 4.7215 | I10: 0 | J10: -4.7215 | K10: 4 | L10: 0.2 | M10: 0 | N10: 0 | O10: 0.073
A11: 7 | B11: 0 | C11: 0 | D11: 0 | E11: 4.224 | F11: 0 | G11: 0 | H11: 4.224 | I11: 0 | J11: -4.224 | K11: 4 | L11: 0.2 | M11: 0 | N11: 0 | O11: 0.073
A12: 8 | B12: 0.019 | C12: 0.019 | D12: 0 | E12: 0.592 | F12: 0 | G12: 0 | H12: 0.611 | I12: 0 | J12: -0.592 | K12: 4 | L12: 0.2 | M12: 0 | N12: 0 | O12: 0.073
A13: 9 | B13: 0.10125 | C13: 0.334 | D13: 0.0365 | E13: 0.00175 | F13: 0.040555556 | G13: 0 | H13: 0.103 | I13: 0 | J13: 0.231 | K13: 4 | L13: 0.20511168 | M13: 0.209475 | N13: 0.23275 | O13: 0.073
A14: 10 | B14: 0.103 | C14: 2.411 | D14: 0.073 | E14: 0 | F14: 0.081111111 | G14: 0 | H14: 0.103 | I14: 0 | J14: 2.308 | K14: 4 | L14: 0.36578121 | M14: 2.0772 | N14: 2.308 | O14: 0.073
... A27: 23 | B27: 0 | C27: 0 | D27: 0 | E27: 3.21125 | F27: 0 | G27: 0 | H27: 3.21125 | I27: 0 | J27: -3.21125 | K27: 4 | L27: 0.2 | M27: 0 | N27: 0 | O27: 0.073
A28: (prázdné) | C28: 0 | D28: 0 | E28: 0 | F28: 0 | G28: 0 | H28: 0 | I28: 0 | J28: 0 | K28: 1 | L28: 0 | M28: 0 | N28: 0 | O28: 0
A29: <00.01.1900 | C29: 0 | D29: 0 | E29: 0 | F29: 0 | G29: 0 | H29: 0 | I29: 0 | J29: 0 | K29: 1 | L29: 0 | M29: 0 | N29: 0 | O29: 0
A30: Celkový součet | B30: 1.9405 | C30: 21.309 | D30: 24.197003 | E30: 42.536997 | F30: 26.885559 | G30: 1.7852562 | H30: 67.7985 | I30: 23.321003 | J30: -46.4895 | K30: 97 | L30: 28.620811 | M30: 15.824919 | N30: 17.583244 | O30: 1.752

Sheet Červenec
A1: Datum | B1: Čas | C1: Spotřeba | D1: Přímá vlastní spotřeba z FVE | E1: Výroba FVE | F1: Odběr z DS | G1: Přetok do DS | H1: Spotřeba z baterie | I1: Bilance | J1: Stav baterie | K1: Soc | L1: Nabíjení (Netto) | M1: Nabíjení (Brutto) | N1: Vybíjení (Netto) | O1: Vybíjení (Brutto) | P1: Vlastní spotřeba
C2: kWh | D2: kwh | E2: kWh | F2: kWh | G2: kWh | H2: kWh | I2: kWh | J2: 15 | K2: % | L2: kWh | M2: kWh | N2: kWh | O2: kWh | P2: kWh
A3: =DATE(2026,7,5) -> 46208 | B3: =TIME(0,0,0) -> 0 | C3: ='Červenec data'!V2+P3 -> 0.062 | D3: =MIN(C3, E3) -> 0 | E3: =ROUND(MAX(0, 13 * EXP(-((HOUR(B3)+MINUTE(B3)/60 - 12.75)^2) / 10) * 0.25 - 0.006), 3) -> 0 | F3: =MAX(0, C3 - D3 - H3 ) -> 0 | G3: =MAX(0, E3 - D3 - M3) -> 0 | H3: =MAX(0, MIN(C3 - D3, N3 )) -> 0.062 | I3: =E3-C3 -> -0.062 | J3: =MIN('Výpočty '!$B$1*0.9, MAX('Výpočty '!$B$1*0.05, J2 + M3 - MIN(O3, MAX(0, J2 - ('Výpočty '!$B$1*0.1))) - P3)) -> 14.892583 | K3: =J3/'Výpočty '!$B$1 -> 0.74462917 | L3: =M3 * Účinnost_cyklu -> 0 | M3: =MIN(MAX(0, I3), MAX(0, Kapacita_baterie * Soc_Max - J2) / Účinnost_cyklu, Stridac_limit) -> 0 | N3: =MAX(0, MIN(J2 - (Kapacita_baterie * Soc_Kriticke), C3 - D3 + P3)) -> 0.08025 | O3: =N3 / Účinnost_cyklu -> 0.089166667 | P3: =Vlastní_Spotřeba_kWh -> 0.01825
